2018-12-07 03:56:15,370 seed_service.py[line:125] ERROR no seed data
2018-12-07 03:56:15,370 seed_service.py[line:44] ERROR get_seed 异常 =no seed data
2018-12-07 03:56:15,370 views.py[line:78] ERROR api get_seed 异常=no seed data
2018-12-07 03:57:08,859 seed_service.py[line:125] ERROR no seed data
2018-12-07 03:57:08,859 seed_service.py[line:44] ERROR get_seed 异常 =no seed data
2018-12-07 03:57:08,859 views.py[line:78] ERROR api get_seed 异常=no seed data
2018-12-07 03:58:16,209 seed_service.py[line:125] ERROR no seed data
2018-12-07 03:58:16,209 seed_service.py[line:44] ERROR get_seed 异常 =no seed data
2018-12-07 03:58:16,209 views.py[line:78] ERROR api get_seed 异常=no seed data
2018-12-07 03:58:31,139 seed_service.py[line:125] ERROR no seed data
2018-12-07 03:58:31,139 seed_service.py[line:44] ERROR get_seed 异常 =no seed data
2018-12-07 03:58:31,139 views.py[line:78] ERROR api get_seed 异常=no seed data
2018-12-07 04:00:33,697 reveal_service.py[line:128] ERROR [async_call_sub] 异常，重试1次 id=24275 roomid=11 game_id=586 =b'\x1b[31mError 3040005: Expired Transaction\x1b[0m\n\x1b[32mPlease increase the expiration time of your transaction!\x1b[0m\n\x1b[33mError Details:\nexpired transaction fce88fd5e3a48680bbd0b2547fa6bf217515e1080437cdf274087893ebd285fc\x1b[0m\n'
2018-12-07 04:01:30,972 seed_service.py[line:125] ERROR no seed data
2018-12-07 04:01:30,972 seed_service.py[line:44] ERROR get_seed 异常 =no seed data
2018-12-07 04:01:30,973 views.py[line:78] ERROR api get_seed 异常=no seed data
2018-12-07 04:27:42,434 reveal_service.py[line:128] ERROR [async_call_sub] 异常，重试1次 id=24428 roomid=11 game_id=617 =b'\x1b[31mError 3050003: eosio_assert_message assertion failure\x1b[0m\n\x1b[33mError Details:\nassertion failure with message: 100013 invalid room status\npending console output: \x1b[0m\n'
2018-12-07 04:48:01,116 reveal_service.py[line:128] ERROR [async_call_sub] 异常，重试1次 id=24544 roomid=11 game_id=640 =b'\x1b[31mError 3050003: eosio_assert_message assertion failure\x1b[0m\n\x1b[33mError Details:\nassertion failure with message: 100013 invalid room status\npending console output: \x1b[0m\n'
2018-12-07 05:07:36,544 reveal_service.py[line:128] ERROR [async_call_sub] 异常，重试1次 id=24654 roomid=11 game_id=662 =b'\x1b[31mError 3050003: eosio_assert_message assertion failure\x1b[0m\n\x1b[33mError Details:\nassertion failure with message: 100013 invalid room status\npending console output: \x1b[0m\n'
2018-12-07 05:27:55,044 reveal_service.py[line:128] ERROR [async_call_sub] 异常，重试1次 id=24768 roomid=1 game_id=2289 =b'\x1b[31mError 3050003: eosio_assert_message assertion failure\x1b[0m\n\x1b[33mError Details:\nassertion failure with message: 100013 invalid room status\npending console output: \x1b[0m\n'
2018-12-07 05:34:09,274 reveal_service.py[line:128] ERROR [async_call_sub] 异常，重试1次 id=24805 roomid=1 game_id=2296 =b'\x1b[31mError 3080001: Account using more than allotted RAM usage\x1b[0m\n\x1b[33mError Details:\naccount ffgamebacara has insufficient ram; needs 2402462 bytes has 2402211 bytes\x1b[0m\n'
2018-12-07 05:34:11,213 reveal_service.py[line:128] ERROR [async_call_sub] 异常，重试2次 id=24805 roomid=1 game_id=2296 =b'\x1b[31mError 3080001: Account using more than allotted RAM usage\x1b[0m\n\x1b[33mError Details:\naccount ffgamebacara has insufficient ram; needs 2403098 bytes has 2402211 bytes\x1b[0m\n'
2018-12-07 05:34:12,533 reveal_service.py[line:128] ERROR [async_call_sub] 异常，重试3次 id=24805 roomid=1 game_id=2296 =b'\x1b[31mError 3080001: Account using more than allotted RAM usage\x1b[0m\n\x1b[33mError Details:\naccount ffgamebacara has insufficient ram; needs 2403098 bytes has 2402211 bytes\x1b[0m\n'
2018-12-07 05:35:03,003 reveal_service.py[line:128] ERROR [async_call_sub] 异常，重试1次 id=24810 roomid=11 game_id=693 =b'\x1b[31mError 3080001: Account using more than allotted RAM usage\x1b[0m\n\x1b[33mError Details:\naccount ffgamebacara has insufficient ram; needs 2402692 bytes has 2402211 bytes\x1b[0m\n'
2018-12-07 05:35:04,325 reveal_service.py[line:128] ERROR [async_call_sub] 异常，重试2次 id=24810 roomid=11 game_id=693 =b'\x1b[31mError 3080001: Account using more than allotted RAM usage\x1b[0m\n\x1b[33mError Details:\naccount ffgamebacara has insufficient ram; needs 2402692 bytes has 2402211 bytes\x1b[0m\n'
2018-12-07 05:35:05,631 reveal_service.py[line:128] ERROR [async_call_sub] 异常，重试3次 id=24810 roomid=11 game_id=693 =b'\x1b[31mError 3080001: Account using more than allotted RAM usage\x1b[0m\n\x1b[33mError Details:\naccount ffgamebacara has insufficient ram; needs 2402692 bytes has 2402211 bytes\x1b[0m\n'
2018-12-07 05:35:20,629 reveal_service.py[line:128] ERROR [async_call_sub] 异常，重试1次 id=24811 roomid=6 game_id=2198 =b'\x1b[31mError 3080001: Account using more than allotted RAM usage\x1b[0m\n\x1b[33mError Details:\naccount ffgamebacara has insufficient ram; needs 2402886 bytes has 2402211 bytes\x1b[0m\n'
2018-12-07 05:35:22,287 reveal_service.py[line:128] ERROR [async_call_sub] 异常，重试2次 id=24811 roomid=6 game_id=2198 =b'\x1b[31mError 3080001: Account using more than allotted RAM usage\x1b[0m\n\x1b[33mError Details:\naccount ffgamebacara has insufficient ram; needs 2403192 bytes has 2402211 bytes\x1b[0m\n'
2018-12-07 05:35:23,933 reveal_service.py[line:128] ERROR [async_call_sub] 异常，重试3次 id=24811 roomid=6 game_id=2198 =b'\x1b[31mError 3080001: Account using more than allotted RAM usage\x1b[0m\n\x1b[33mError Details:\naccount ffgamebacara has insufficient ram; needs 2403192 bytes has 2402211 bytes\x1b[0m\n'
2018-12-07 05:35:53,998 reveal_service.py[line:128] ERROR [async_call_sub] 异常，重试1次 id=24812 roomid=12 game_id=217 =b'\x1b[31mError 3080001: Account using more than allotted RAM usage\x1b[0m\n\x1b[33mError Details:\naccount ffgamebacara has insufficient ram; needs 2402280 bytes has 2402211 bytes\x1b[0m\n'
2018-12-07 05:35:55,490 reveal_service.py[line:128] ERROR [async_call_sub] 异常，重试2次 id=24812 roomid=12 game_id=217 =b'\x1b[31mError 3080001: Account using more than allotted RAM usage\x1b[0m\n\x1b[33mError Details:\naccount ffgamebacara has insufficient ram; needs 2402215 bytes has 2402211 bytes\x1b[0m\n'
2018-12-07 05:35:57,502 reveal_service.py[line:128] ERROR [async_call_sub] 异常，重试3次 id=24812 roomid=12 game_id=217 =b'\x1b[31mError 3080001: Account using more than allotted RAM usage\x1b[0m\n\x1b[33mError Details:\naccount ffgamebacara has insufficient ram; needs 2402215 bytes has 2402211 bytes\x1b[0m\n'
2018-12-07 05:39:27,833 connector.py[line:28] ERROR invalid room status roomid=13 gameid=1 异常已被处理
2018-12-07 05:39:28,088 connector.py[line:28] ERROR invalid room status roomid=13 gameid=1 异常已被处理
2018-12-07 05:39:28,585 connector.py[line:28] ERROR invalid room status roomid=13 gameid=1 异常已被处理
2018-12-07 05:39:28,871 reveal_service.py[line:144] ERROR 〓REVEAL〓 房间新建后第一次开奖，且无人下注 开奖失败 roomid=13 (pymysql.err.IntegrityError) (1062, "Duplicate entry '13-2' for key 'uix_id_name'") [SQL: 'INSERT INTO room_seed (room_id, game_id, house_seed_hash, house_seed, expire_timestamp, signature, status, fail_count, created_at, environment) VALUES (%(room_id)s, %(game_id)s, %(house_seed_hash)s, %(house_seed)s, %(expire_timestamp)s, %(signature)s, %(status)s, %(fail_count)s, %(created_at)s, %(environment)s)'] [parameters: {'room_id': 13, 'game_id': 2, 'house_seed_hash': 'e428539e8d7bbd518dcecae7c5c73f45c9da6615919b64ac208a02e5f298adad', 'house_seed': '89745e8109a30d71851f7395614a40cf19b67f985e1ea5267b3dc0490c8031c7', 'expire_timestamp': 1544161287, 'signature': 'SIG_K1_KfkX66YjgaEqynBhAQosNmDkh5fHWhrcRcWBqCYdbBeZ6XeFRG3Q9Q5JbnmJAUyjVJVV52rpMuLhQhLmSpQ5acznVttsuz', 'status': 1, 'fail_count': 0, 'created_at': 1544161168.7365992, 'environment': 'PRO'}] (Background on this error at: http://sqlalche.me/e/gkpj)
2018-12-07 05:39:29,312 reveal_service.py[line:144] ERROR 〓REVEAL〓 房间新建后第一次开奖，且无人下注 开奖失败 roomid=13 (pymysql.err.IntegrityError) (1062, "Duplicate entry '13-2' for key 'uix_id_name'") [SQL: 'INSERT INTO room_seed (room_id, game_id, house_seed_hash, house_seed, expire_timestamp, signature, status, fail_count, created_at, environment) VALUES (%(room_id)s, %(game_id)s, %(house_seed_hash)s, %(house_seed)s, %(expire_timestamp)s, %(signature)s, %(status)s, %(fail_count)s, %(created_at)s, %(environment)s)'] [parameters: {'room_id': 13, 'game_id': 2, 'house_seed_hash': 'db7819179f01c2b48ed6ffc54d145681f452499c69a25c50b47ffc5f244992ba', 'house_seed': '3c9116291b5e7526f3e91f21833e07b8cdfec28356c77d2f0c1f8c4665ed1c92', 'expire_timestamp': 1544161288, 'signature': 'SIG_K1_Kcprh7vQRkKEhX43HNqaihW36FXghLSP6q1n4SudnU1TkhNEpVhFguhmu5kupekQ1BqcpJTw9dp3i85eXe6JPAc293YCkm', 'status': 1, 'fail_count': 0, 'created_at': 1544161169.2566843, 'environment': 'PRO'}] (Background on this error at: http://sqlalche.me/e/gkpj)
2018-12-07 05:39:29,597 reveal_service.py[line:144] ERROR 〓REVEAL〓 房间新建后第一次开奖，且无人下注 开奖失败 roomid=13 (pymysql.err.IntegrityError) (1062, "Duplicate entry '13-2' for key 'uix_id_name'") [SQL: 'INSERT INTO room_seed (room_id, game_id, house_seed_hash, house_seed, expire_timestamp, signature, status, fail_count, created_at, environment) VALUES (%(room_id)s, %(game_id)s, %(house_seed_hash)s, %(house_seed)s, %(expire_timestamp)s, %(signature)s, %(status)s, %(fail_count)s, %(created_at)s, %(environment)s)'] [parameters: {'room_id': 13, 'game_id': 2, 'house_seed_hash': 'ada3fd3854ebc3bec75377b8bd1e6ed0d1ccb3bf2f4d345619c0f1c75b39d913', 'house_seed': '778e319ce25b69fca5971cfbb859b9b3e90d248dc4713cc226b176c494b754e5', 'expire_timestamp': 1544161288, 'signature': 'SIG_K1_K4oMVvVZFnQgqyADNm5QAnLJ3gfez2cvYraSQLASvVtPC5yBP3opRN16MQkB9RztAX1seqDd4NcVUqGzBrRNV12Nvgso5X', 'status': 1, 'fail_count': 0, 'created_at': 1544161169.5933113, 'environment': 'PRO'}] (Background on this error at: http://sqlalche.me/e/gkpj)
2018-12-07 05:40:56,184 connector.py[line:28] ERROR invalid room status roomid=14 gameid=1 异常已被处理
2018-12-07 05:40:56,286 connector.py[line:28] ERROR invalid room status roomid=14 gameid=1 异常已被处理
2018-12-07 05:40:56,294 connector.py[line:28] ERROR invalid room status roomid=14 gameid=1 异常已被处理
2018-12-07 05:40:56,909 reveal_service.py[line:144] ERROR 〓REVEAL〓 房间新建后第一次开奖，且无人下注 开奖失败 roomid=14 (pymysql.err.IntegrityError) (1062, "Duplicate entry '14-2' for key 'uix_id_name'") [SQL: 'INSERT INTO room_seed (room_id, game_id, house_seed_hash, house_seed, expire_timestamp, signature, status, fail_count, created_at, environment) VALUES (%(room_id)s, %(game_id)s, %(house_seed_hash)s, %(house_seed)s, %(expire_timestamp)s, %(signature)s, %(status)s, %(fail_count)s, %(created_at)s, %(environment)s)'] [parameters: {'room_id': 14, 'game_id': 2, 'house_seed_hash': '94e1e65c47a6ca0ffaec54fe7230326f4f7bc92e08cbeaec2a014076b86f3ffa', 'house_seed': '7bab884d499054ed938cc3f80784c2f9c97c4eac3e0b737d83959ecea6aab117', 'expire_timestamp': 1544161376, 'signature': 'SIG_K1_K5tWaHJGwHtAz7HTZ4hGUofcdEbd5uU34ZJYpSB1rEn7AC8y5mr4fsWFr5xNsoTZvYw4EMMTJNZvZoFTvMFAjCJ3M5fw9m', 'status': 1, 'fail_count': 0, 'created_at': 1544161256.8502667, 'environment': 'PRO'}] (Background on this error at: http://sqlalche.me/e/gkpj)
2018-12-07 05:40:57,281 reveal_service.py[line:144] ERROR 〓REVEAL〓 房间新建后第一次开奖，且无人下注 开奖失败 roomid=14 (pymysql.err.IntegrityError) (1062, "Duplicate entry '14-2' for key 'uix_id_name'") [SQL: 'INSERT INTO room_seed (room_id, game_id, house_seed_hash, house_seed, expire_timestamp, signature, status, fail_count, created_at, environment) VALUES (%(room_id)s, %(game_id)s, %(house_seed_hash)s, %(house_seed)s, %(expire_timestamp)s, %(signature)s, %(status)s, %(fail_count)s, %(created_at)s, %(environment)s)'] [parameters: {'room_id': 14, 'game_id': 2, 'house_seed_hash': 'd05ec450225cac0d69745cfbfe58359a3b6259b39984ad7e3899eaff752713e0', 'house_seed': '3e085a6dea1115653114326ccbf62f78be836c44973c850e4cb76bcf49ca6ca1', 'expire_timestamp': 1544161376, 'signature': 'SIG_K1_KkajRQprisBu18xYEfsTeLZ7CwBC4Mt8hTJp6xhH2GNbxbUVFB9GDdtAeTfYjz1D98DBkcsBntwt2xZSVYV8PLMAd82yXT', 'status': 1, 'fail_count': 0, 'created_at': 1544161257.1961954, 'environment': 'PRO'}] (Background on this error at: http://sqlalche.me/e/gkpj)
2018-12-07 05:40:57,447 reveal_service.py[line:144] ERROR 〓REVEAL〓 房间新建后第一次开奖，且无人下注 开奖失败 roomid=14 (pymysql.err.IntegrityError) (1062, "Duplicate entry '14-2' for key 'uix_id_name'") [SQL: 'INSERT INTO room_seed (room_id, game_id, house_seed_hash, house_seed, expire_timestamp, signature, status, fail_count, created_at, environment) VALUES (%(room_id)s, %(game_id)s, %(house_seed_hash)s, %(house_seed)s, %(expire_timestamp)s, %(signature)s, %(status)s, %(fail_count)s, %(created_at)s, %(environment)s)'] [parameters: {'room_id': 14, 'game_id': 2, 'house_seed_hash': '0abbe8fe79895d0adf276c15dc6cd1c0deb2aeade3329f3ca1578c468a57ec6d', 'house_seed': '74ceb26e6a2974a0c4a1162fe8b8e00f7f78a5a8bb9fcd07cdfa2b951493ff89', 'expire_timestamp': 1544161376, 'signature': 'SIG_K1_KaMeHfQYdP8VBzsWqS5HB8x8VrSaqAywtjwJcoD9g5s9cW4TQnGUnVNExPW4UizkRre6qSYXkrDcET2Hgn1zTLw4YeYvpR', 'status': 1, 'fail_count': 0, 'created_at': 1544161257.4429693, 'environment': 'PRO'}] (Background on this error at: http://sqlalche.me/e/gkpj)
2018-12-07 05:42:03,630 connector.py[line:28] ERROR invalid room status roomid=15 gameid=1 异常已被处理
2018-12-07 05:42:03,697 connector.py[line:28] ERROR invalid room status roomid=15 gameid=1 异常已被处理
2018-12-07 05:42:03,871 connector.py[line:28] ERROR invalid room status roomid=15 gameid=1 异常已被处理
2018-12-07 05:42:04,229 connector.py[line:28] ERROR invalid room status roomid=15 gameid=1 异常已被处理
2018-12-07 05:42:05,100 connector.py[line:28] ERROR invalid room status roomid=15 gameid=1 异常已被处理
2018-12-07 05:42:05,123 reveal_service.py[line:144] ERROR 〓REVEAL〓 房间新建后第一次开奖，且无人下注 开奖失败 roomid=15 (pymysql.err.IntegrityError) (1062, "Duplicate entry '15-2' for key 'uix_id_name'") [SQL: 'INSERT INTO room_seed (room_id, game_id, house_seed_hash, house_seed, expire_timestamp, signature, status, fail_count, created_at, environment) VALUES (%(room_id)s, %(game_id)s, %(house_seed_hash)s, %(house_seed)s, %(expire_timestamp)s, %(signature)s, %(status)s, %(fail_count)s, %(created_at)s, %(environment)s)'] [parameters: {'room_id': 15, 'game_id': 2, 'house_seed_hash': '49bfac1ed9b18e9b27a91b09dd929e1e097d6edd282dae81f581976c81c58bce', 'house_seed': '670445526d782e2423cf886055fcb6650ae54c2ddbc43c11090ddad9f90fdae3', 'expire_timestamp': 1544161443, 'signature': 'SIG_K1_KBRUT8uWpn2iyeD5jAuyv7vfDqtExuEd1Y7w9RQVyNegvCq2NNbWSVRTmEx4nPDA52jcAMbEMz8B66YYkKEMwLSxuXsDRP', 'status': 1, 'fail_count': 0, 'created_at': 1544161324.8688653, 'environment': 'PRO'}] (Background on this error at: http://sqlalche.me/e/gkpj)
2018-12-07 05:42:05,519 reveal_service.py[line:144] ERROR 〓REVEAL〓 房间新建后第一次开奖，且无人下注 开奖失败 roomid=15 (pymysql.err.IntegrityError) (1062, "Duplicate entry '15-2' for key 'uix_id_name'") [SQL: 'INSERT INTO room_seed (room_id, game_id, house_seed_hash, house_seed, expire_timestamp, signature, status, fail_count, created_at, environment) VALUES (%(room_id)s, %(game_id)s, %(house_seed_hash)s, %(house_seed)s, %(expire_timestamp)s, %(signature)s, %(status)s, %(fail_count)s, %(created_at)s, %(environment)s)'] [parameters: {'room_id': 15, 'game_id': 2, 'house_seed_hash': 'aac4bb86904ee27e8bc775cb9e56b4f6bc9d4498ab40bb6cbb4c1d2cd51a53d5', 'house_seed': 'deadf197b4072cc4a3cf08894d46931218b404ee64daf9abb312379d0feff5ff', 'expire_timestamp': 1544161443, 'signature': 'SIG_K1_Kd4npmqiyJYjvBexWLSyLJYw6QJQgZGgphypq6vqsTPme7rzpm8u3UBh8qdSvc7gTsMJ97LcbWjR5zGHXHNnmPLgt8BViW', 'status': 1, 'fail_count': 0, 'created_at': 1544161325.1573083, 'environment': 'PRO'}] (Background on this error at: http://sqlalche.me/e/gkpj)
2018-12-07 05:42:05,919 reveal_service.py[line:144] ERROR 〓REVEAL〓 房间新建后第一次开奖，且无人下注 开奖失败 roomid=15 (pymysql.err.IntegrityError) (1062, "Duplicate entry '15-2' for key 'uix_id_name'") [SQL: 'INSERT INTO room_seed (room_id, game_id, house_seed_hash, house_seed, expire_timestamp, signature, status, fail_count, created_at, environment) VALUES (%(room_id)s, %(game_id)s, %(house_seed_hash)s, %(house_seed)s, %(expire_timestamp)s, %(signature)s, %(status)s, %(fail_count)s, %(created_at)s, %(environment)s)'] [parameters: {'room_id': 15, 'game_id': 2, 'house_seed_hash': '6b1da4b7d11a59ace56dd43255c4792343d70ed90887717ce9fa00fc1f152c13', 'house_seed': '20cff1b788b8cbec5204f389d8524c7bc33cc6d9b6f22906a18b755b1c07bf2a', 'expire_timestamp': 1544161445, 'signature': 'SIG_K1_K81rEQJ4ryViiVviFNjyPhKcbzVGBa3R2XEbSfYHJ9cDSCdYgcutix94zjjUUbKujLsksVwL5RJyiGtZFCUZ1fZ3KUZxFh', 'status': 1, 'fail_count': 0, 'created_at': 1544161325.8637204, 'environment': 'PRO'}] (Background on this error at: http://sqlalche.me/e/gkpj)
2018-12-07 05:42:06,017 reveal_service.py[line:144] ERROR 〓REVEAL〓 房间新建后第一次开奖，且无人下注 开奖失败 roomid=15 (pymysql.err.IntegrityError) (1062, "Duplicate entry '15-2' for key 'uix_id_name'") [SQL: 'INSERT INTO room_seed (room_id, game_id, house_seed_hash, house_seed, expire_timestamp, signature, status, fail_count, created_at, environment) VALUES (%(room_id)s, %(game_id)s, %(house_seed_hash)s, %(house_seed)s, %(expire_timestamp)s, %(signature)s, %(status)s, %(fail_count)s, %(created_at)s, %(environment)s)'] [parameters: {'room_id': 15, 'game_id': 2, 'house_seed_hash': 'bb65d83718553e8440e365400d7415b0da3d7afc71b384dd830ef11095200095', 'house_seed': '871a1e218a006b9b5e1733e4ae3a680a6427564575978b4f609931726fcef22f', 'expire_timestamp': 1544161444, 'signature': 'SIG_K1_KBBGCdFGuEJaFBNJky1Gx78KjHtDMnRpr3iyKkd1WKhZ6CRaZbEHYnXspp7mmmx23Qyt1LvkgQJHKyDeQt2dBWDiG4vyZE', 'status': 1, 'fail_count': 0, 'created_at': 1544161325.986221, 'environment': 'PRO'}] (Background on this error at: http://sqlalche.me/e/gkpj)
2018-12-07 05:42:06,028 reveal_service.py[line:144] ERROR 〓REVEAL〓 房间新建后第一次开奖，且无人下注 开奖失败 roomid=15 (pymysql.err.IntegrityError) (1062, "Duplicate entry '15-2' for key 'uix_id_name'") [SQL: 'INSERT INTO room_seed (room_id, game_id, house_seed_hash, house_seed, expire_timestamp, signature, status, fail_count, created_at, environment) VALUES (%(room_id)s, %(game_id)s, %(house_seed_hash)s, %(house_seed)s, %(expire_timestamp)s, %(signature)s, %(status)s, %(fail_count)s, %(created_at)s, %(environment)s)'] [parameters: {'room_id': 15, 'game_id': 2, 'house_seed_hash': '8bed4b7fb858537e34f12069db939135be35c4dbbcea03a7b5f58dfc88a3b00c', 'house_seed': 'd13e0df077283eb86ece7547f3bfd43e360288ebeaa525620c9abf14ccbf4291', 'expire_timestamp': 1544161443, 'signature': 'SIG_K1_KYNUMKpPWrT7sDSWN7dun1gHLMRVMVVaYokbTqtzEArptEjBLr2LP3Gg2QfoDUi3jfcEHmQEbGyKcaq37aancpA5nNRF7W', 'status': 1, 'fail_count': 0, 'created_at': 1544161325.998948, 'environment': 'PRO'}] (Background on this error at: http://sqlalche.me/e/gkpj)
2018-12-07 05:42:28,311 connector.py[line:28] ERROR invalid room status roomid=16 gameid=1 异常已被处理
2018-12-07 05:42:28,546 connector.py[line:28] ERROR invalid room status roomid=16 gameid=1 异常已被处理
2018-12-07 05:42:28,995 connector.py[line:28] ERROR invalid room status roomid=16 gameid=1 异常已被处理
2018-12-07 05:42:29,018 connector.py[line:28] ERROR invalid room status roomid=16 gameid=1 异常已被处理
2018-12-07 05:42:29,342 reveal_service.py[line:144] ERROR 〓REVEAL〓 房间新建后第一次开奖，且无人下注 开奖失败 roomid=16 (pymysql.err.IntegrityError) (1062, "Duplicate entry '16-2' for key 'uix_id_name'") [SQL: 'INSERT INTO room_seed (room_id, game_id, house_seed_hash, house_seed, expire_timestamp, signature, status, fail_count, created_at, environment) VALUES (%(room_id)s, %(game_id)s, %(house_seed_hash)s, %(house_seed)s, %(expire_timestamp)s, %(signature)s, %(status)s, %(fail_count)s, %(created_at)s, %(environment)s)'] [parameters: {'room_id': 16, 'game_id': 2, 'house_seed_hash': 'ebe5f98643610d8f07ea12985525cdd2b2b75fc7587ba96f8dcb5408deca30d5', 'house_seed': '0acc9c0538682e5d7eec2649941eb44ffcff02e16ac4300c751b8343b6aea798', 'expire_timestamp': 1544161468, 'signature': 'SIG_K1_JyJgjge2ZCRM29WWV4WLz7YADKuxGPH9SfVFmzuTTAdDS3SKjwbVnG6Q9nHumUP6JccKgDhyXsqS3XqsnM4wvbK2gsRoWU', 'status': 1, 'fail_count': 0, 'created_at': 1544161349.2573497, 'environment': 'PRO'}] (Background on this error at: http://sqlalche.me/e/gkpj)
2018-12-07 05:42:30,410 reveal_service.py[line:144] ERROR 〓REVEAL〓 房间新建后第一次开奖，且无人下注 开奖失败 roomid=16 (pymysql.err.IntegrityError) (1062, "Duplicate entry '16-2' for key 'uix_id_name'") [SQL: 'INSERT INTO room_seed (room_id, game_id, house_seed_hash, house_seed, expire_timestamp, signature, status, fail_count, created_at, environment) VALUES (%(room_id)s, %(game_id)s, %(house_seed_hash)s, %(house_seed)s, %(expire_timestamp)s, %(signature)s, %(status)s, %(fail_count)s, %(created_at)s, %(environment)s)'] [parameters: {'room_id': 16, 'game_id': 2, 'house_seed_hash': 'afe9048f96327f98ca7be10ca040e35639f186167d5b1c07f7e735a9ef869a37', 'house_seed': 'c3e5c1a42c39be7cd6a718f298d01b40b75cff0af903f5b2ba166f98f47f60c4', 'expire_timestamp': 1544161469, 'signature': 'SIG_K1_JzvUTJ18mTZFva45kEK6YGsBqKc7UCRJiPKWYt2L2Jm3D4tV9enuHSytHznMBA8hoP387UNrQMf32i6jHUSNtUEAmXKFXC', 'status': 1, 'fail_count': 0, 'created_at': 1544161350.3586175, 'environment': 'PRO'}] (Background on this error at: http://sqlalche.me/e/gkpj)
2018-12-07 05:42:30,481 reveal_service.py[line:144] ERROR 〓REVEAL〓 房间新建后第一次开奖，且无人下注 开奖失败 roomid=16 (pymysql.err.IntegrityError) (1062, "Duplicate entry '16-2' for key 'uix_id_name'") [SQL: 'INSERT INTO room_seed (room_id, game_id, house_seed_hash, house_seed, expire_timestamp, signature, status, fail_count, created_at, environment) VALUES (%(room_id)s, %(game_id)s, %(house_seed_hash)s, %(house_seed)s, %(expire_timestamp)s, %(signature)s, %(status)s, %(fail_count)s, %(created_at)s, %(environment)s)'] [parameters: {'room_id': 16, 'game_id': 2, 'house_seed_hash': 'e9e438183d3c4fe9ee5f68f300e5ebc256cd465da73fdd9fb96fdfefd5e5ad62', 'house_seed': '5028fe6608bb087038985797e4d669f95ed342f5d6e66a9c9aa1d62bbcb5d6ab', 'expire_timestamp': 1544161468, 'signature': 'SIG_K1_Kkbf6aBq4vq3LFWidHoD6Yn5g9zL5p5xjDKaEWD6A3U8aynvrotommHFKzKNCmVwf9VYrQs5ok1vjVUneeaYAAEgsoQEUS', 'status': 1, 'fail_count': 0, 'created_at': 1544161350.405021, 'environment': 'PRO'}] (Background on this error at: http://sqlalche.me/e/gkpj)
2018-12-07 05:42:30,765 reveal_service.py[line:144] ERROR 〓REVEAL〓 房间新建后第一次开奖，且无人下注 开奖失败 roomid=16 (pymysql.err.IntegrityError) (1062, "Duplicate entry '16-2' for key 'uix_id_name'") [SQL: 'INSERT INTO room_seed (room_id, game_id, house_seed_hash, house_seed, expire_timestamp, signature, status, fail_count, created_at, environment) VALUES (%(room_id)s, %(game_id)s, %(house_seed_hash)s, %(house_seed)s, %(expire_timestamp)s, %(signature)s, %(status)s, %(fail_count)s, %(created_at)s, %(environment)s)'] [parameters: {'room_id': 16, 'game_id': 2, 'house_seed_hash': '7a9053046de4ba57346c82ea4370b82bb0e20f0ec989b8997890be3ba81d1eb4', 'house_seed': 'c96a12aef60cd930d04d11e830bfc147164f8806a25c57712abb626fceb3d804', 'expire_timestamp': 1544161469, 'signature': 'SIG_K1_KY1BFXU5us7LMU4nXYE6TVSimaWYrP79FCaCtYdQmMAzbUQ8K3DW9ca4UBvzkabYVy1wdek4rngStaWgaokExPFTCeRpXx', 'status': 1, 'fail_count': 0, 'created_at': 1544161350.7316625, 'environment': 'PRO'}] (Background on this error at: http://sqlalche.me/e/gkpj)
2018-12-07 05:42:31,024 reveal_service.py[line:144] ERROR 〓REVEAL〓 房间新建后第一次开奖，且无人下注 开奖失败 roomid=16 (pymysql.err.IntegrityError) (1062, "Duplicate entry '16-2' for key 'uix_id_name'") [SQL: 'INSERT INTO room_seed (room_id, game_id, house_seed_hash, house_seed, expire_timestamp, signature, status, fail_count, created_at, environment) VALUES (%(room_id)s, %(game_id)s, %(house_seed_hash)s, %(house_seed)s, %(expire_timestamp)s, %(signature)s, %(status)s, %(fail_count)s, %(created_at)s, %(environment)s)'] [parameters: {'room_id': 16, 'game_id': 2, 'house_seed_hash': '85b6d5a5f39932af5d7ad95435f30486b6201376e529ac292a80bdd365e6a590', 'house_seed': 'cefaf104935f2c5a6cfc5684b223fda9964ddf3bfa7c762c2c55573c10e31a64', 'expire_timestamp': 1544161469, 'signature': 'SIG_K1_KbJ73ayrLJDvQwW9JCVFLH1q2APGK5vw2AXhi1zhecxHxmUAGmaPTqxrYFvfUbqeh5jQFeqVeo8Hv3daXZEMmb3RJB1njs', 'status': 1, 'fail_count': 0, 'created_at': 1544161351.0198648, 'environment': 'PRO'}] (Background on this error at: http://sqlalche.me/e/gkpj)
2018-12-07 05:44:08,507 reveal_service.py[line:144] ERROR 〓REVEAL〓 房间新建后第一次开奖，且无人下注 开奖失败 roomid=17 b'\x1b[31mError 3050003: eosio_assert_message assertion failure\x1b[0m\n\x1b[33mError Details:\nassertion failure with message: 100016 room not found\npending console output: \x1b[0m\n'
2018-12-07 05:44:08,568 reveal_service.py[line:144] ERROR 〓REVEAL〓 房间新建后第一次开奖，且无人下注 开奖失败 roomid=17 b'\x1b[31mError 3050003: eosio_assert_message assertion failure\x1b[0m\n\x1b[33mError Details:\nassertion failure with message: 100016 room not found\npending console output: \x1b[0m\n'
2018-12-07 05:44:08,936 reveal_service.py[line:144] ERROR 〓REVEAL〓 房间新建后第一次开奖，且无人下注 开奖失败 roomid=17 b'\x1b[31mError 3050003: eosio_assert_message assertion failure\x1b[0m\n\x1b[33mError Details:\nassertion failure with message: 100016 room not found\npending console output: \x1b[0m\n'
2018-12-07 05:44:08,979 reveal_service.py[line:144] ERROR 〓REVEAL〓 房间新建后第一次开奖，且无人下注 开奖失败 roomid=17 b'\x1b[31mError 3050003: eosio_assert_message assertion failure\x1b[0m\n\x1b[33mError Details:\nassertion failure with message: 100016 room not found\npending console output: \x1b[0m\n'
2018-12-07 05:44:09,327 reveal_service.py[line:144] ERROR 〓REVEAL〓 房间新建后第一次开奖，且无人下注 开奖失败 roomid=17 b'\x1b[31mError 3050003: eosio_assert_message assertion failure\x1b[0m\n\x1b[33mError Details:\nassertion failure with message: 100016 room not found\npending console output: \x1b[0m\n'
