2018-12-07 03:56:15,370 seed_service.py[line:125] ERROR no seed data
2018-12-07 03:56:15,370 seed_service.py[line:44] ERROR get_seed 异常 =no seed data
2018-12-07 03:56:15,370 views.py[line:78] ERROR api get_seed 异常=no seed data
2018-12-07 03:57:08,859 seed_service.py[line:125] ERROR no seed data
2018-12-07 03:57:08,859 seed_service.py[line:44] ERROR get_seed 异常 =no seed data
2018-12-07 03:57:08,859 views.py[line:78] ERROR api get_seed 异常=no seed data
2018-12-07 03:58:16,209 seed_service.py[line:125] ERROR no seed data
2018-12-07 03:58:16,209 seed_service.py[line:44] ERROR get_seed 异常 =no seed data
2018-12-07 03:58:16,209 views.py[line:78] ERROR api get_seed 异常=no seed data
2018-12-07 03:58:31,139 seed_service.py[line:125] ERROR no seed data
2018-12-07 03:58:31,139 seed_service.py[line:44] ERROR get_seed 异常 =no seed data
2018-12-07 03:58:31,139 views.py[line:78] ERROR api get_seed 异常=no seed data
2018-12-07 04:00:33,697 reveal_service.py[line:128] ERROR [async_call_sub] 异常，重试1次 id=24275 roomid=11 game_id=586 =b'\x1b[31mError 3040005: Expired Transaction\x1b[0m\n\x1b[32mPlease increase the expiration time of your transaction!\x1b[0m\n\x1b[33mError Details:\nexpired transaction fce88fd5e3a48680bbd0b2547fa6bf217515e1080437cdf274087893ebd285fc\x1b[0m\n'
2018-12-07 04:01:30,972 seed_service.py[line:125] ERROR no seed data
2018-12-07 04:01:30,972 seed_service.py[line:44] ERROR get_seed 异常 =no seed data
2018-12-07 04:01:30,973 views.py[line:78] ERROR api get_seed 异常=no seed data
2018-12-07 04:27:42,434 reveal_service.py[line:128] ERROR [async_call_sub] 异常，重试1次 id=24428 roomid=11 game_id=617 =b'\x1b[31mError 3050003: eosio_assert_message assertion failure\x1b[0m\n\x1b[33mError Details:\nassertion failure with message: 100013 invalid room status\npending console output: \x1b[0m\n'
2018-12-07 04:48:01,116 reveal_service.py[line:128] ERROR [async_call_sub] 异常，重试1次 id=24544 roomid=11 game_id=640 =b'\x1b[31mError 3050003: eosio_assert_message assertion failure\x1b[0m\n\x1b[33mError Details:\nassertion failure with message: 100013 invalid room status\npending console output: \x1b[0m\n'
2018-12-07 05:07:36,544 reveal_service.py[line:128] ERROR [async_call_sub] 异常，重试1次 id=24654 roomid=11 game_id=662 =b'\x1b[31mError 3050003: eosio_assert_message assertion failure\x1b[0m\n\x1b[33mError Details:\nassertion failure with message: 100013 invalid room status\npending console output: \x1b[0m\n'
2018-12-07 05:27:55,044 reveal_service.py[line:128] ERROR [async_call_sub] 异常，重试1次 id=24768 roomid=1 game_id=2289 =b'\x1b[31mError 3050003: eosio_assert_message assertion failure\x1b[0m\n\x1b[33mError Details:\nassertion failure with message: 100013 invalid room status\npending console output: \x1b[0m\n'
2018-12-07 05:34:09,274 reveal_service.py[line:128] ERROR [async_call_sub] 异常，重试1次 id=24805 roomid=1 game_id=2296 =b'\x1b[31mError 3080001: Account using more than allotted RAM usage\x1b[0m\n\x1b[33mError Details:\naccount ffgamebacara has insufficient ram; needs 2402462 bytes has 2402211 bytes\x1b[0m\n'
2018-12-07 05:34:11,213 reveal_service.py[line:128] ERROR [async_call_sub] 异常，重试2次 id=24805 roomid=1 game_id=2296 =b'\x1b[31mError 3080001: Account using more than allotted RAM usage\x1b[0m\n\x1b[33mError Details:\naccount ffgamebacara has insufficient ram; needs 2403098 bytes has 2402211 bytes\x1b[0m\n'
2018-12-07 05:34:12,533 reveal_service.py[line:128] ERROR [async_call_sub] 异常，重试3次 id=24805 roomid=1 game_id=2296 =b'\x1b[31mError 3080001: Account using more than allotted RAM usage\x1b[0m\n\x1b[33mError Details:\naccount ffgamebacara has insufficient ram; needs 2403098 bytes has 2402211 bytes\x1b[0m\n'
2018-12-07 05:35:03,003 reveal_service.py[line:128] ERROR [async_call_sub] 异常，重试1次 id=24810 roomid=11 game_id=693 =b'\x1b[31mError 3080001: Account using more than allotted RAM usage\x1b[0m\n\x1b[33mError Details:\naccount ffgamebacara has insufficient ram; needs 2402692 bytes has 2402211 bytes\x1b[0m\n'
2018-12-07 05:35:04,325 reveal_service.py[line:128] ERROR [async_call_sub] 异常，重试2次 id=24810 roomid=11 game_id=693 =b'\x1b[31mError 3080001: Account using more than allotted RAM usage\x1b[0m\n\x1b[33mError Details:\naccount ffgamebacara has insufficient ram; needs 2402692 bytes has 2402211 bytes\x1b[0m\n'
2018-12-07 05:35:05,631 reveal_service.py[line:128] ERROR [async_call_sub] 异常，重试3次 id=24810 roomid=11 game_id=693 =b'\x1b[31mError 3080001: Account using more than allotted RAM usage\x1b[0m\n\x1b[33mError Details:\naccount ffgamebacara has insufficient ram; needs 2402692 bytes has 2402211 bytes\x1b[0m\n'
2018-12-07 05:35:20,629 reveal_service.py[line:128] ERROR [async_call_sub] 异常，重试1次 id=24811 roomid=6 game_id=2198 =b'\x1b[31mError 3080001: Account using more than allotted RAM usage\x1b[0m\n\x1b[33mError Details:\naccount ffgamebacara has insufficient ram; needs 2402886 bytes has 2402211 bytes\x1b[0m\n'
2018-12-07 05:35:22,287 reveal_service.py[line:128] ERROR [async_call_sub] 异常，重试2次 id=24811 roomid=6 game_id=2198 =b'\x1b[31mError 3080001: Account using more than allotted RAM usage\x1b[0m\n\x1b[33mError Details:\naccount ffgamebacara has insufficient ram; needs 2403192 bytes has 2402211 bytes\x1b[0m\n'
2018-12-07 05:35:23,933 reveal_service.py[line:128] ERROR [async_call_sub] 异常，重试3次 id=24811 roomid=6 game_id=2198 =b'\x1b[31mError 3080001: Account using more than allotted RAM usage\x1b[0m\n\x1b[33mError Details:\naccount ffgamebacara has insufficient ram; needs 2403192 bytes has 2402211 bytes\x1b[0m\n'
2018-12-07 05:35:53,998 reveal_service.py[line:128] ERROR [async_call_sub] 异常，重试1次 id=24812 roomid=12 game_id=217 =b'\x1b[31mError 3080001: Account using more than allotted RAM usage\x1b[0m\n\x1b[33mError Details:\naccount ffgamebacara has insufficient ram; needs 2402280 bytes has 2402211 bytes\x1b[0m\n'
2018-12-07 05:35:55,490 reveal_service.py[line:128] ERROR [async_call_sub] 异常，重试2次 id=24812 roomid=12 game_id=217 =b'\x1b[31mError 3080001: Account using more than allotted RAM usage\x1b[0m\n\x1b[33mError Details:\naccount ffgamebacara has insufficient ram; needs 2402215 bytes has 2402211 bytes\x1b[0m\n'
2018-12-07 05:35:57,502 reveal_service.py[line:128] ERROR [async_call_sub] 异常，重试3次 id=24812 roomid=12 game_id=217 =b'\x1b[31mError 3080001: Account using more than allotted RAM usage\x1b[0m\n\x1b[33mError Details:\naccount ffgamebacara has insufficient ram; needs 2402215 bytes has 2402211 bytes\x1b[0m\n'
2018-12-07 05:39:27,833 connector.py[line:28] ERROR invalid room status roomid=13 gameid=1 异常已被处理
2018-12-07 05:39:28,088 connector.py[line:28] ERROR invalid room status roomid=13 gameid=1 异常已被处理
2018-12-07 05:39:28,585 connector.py[line:28] ERROR invalid room status roomid=13 gameid=1 异常已被处理
2018-12-07 05:39:28,871 reveal_service.py[line:144] ERROR 〓REVEAL〓 房间新建后第一次开奖，且无人下注 开奖失败 roomid=13 (pymysql.err.IntegrityError) (1062, "Duplicate entry '13-2' for key 'uix_id_name'") [SQL: 'INSERT INTO room_seed (room_id, game_id, house_seed_hash, house_seed, expire_timestamp, signature, status, fail_count, created_at, environment) VALUES (%(room_id)s, %(game_id)s, %(house_seed_hash)s, %(house_seed)s, %(expire_timestamp)s, %(signature)s, %(status)s, %(fail_count)s, %(created_at)s, %(environment)s)'] [parameters: {'room_id': 13, 'game_id': 2, 'house_seed_hash': 'e428539e8d7bbd518dcecae7c5c73f45c9da6615919b64ac208a02e5f298adad', 'house_seed': '89745e8109a30d71851f7395614a40cf19b67f985e1ea5267b3dc0490c8031c7', 'expire_timestamp': 1544161287, 'signature': 'SIG_K1_KfkX66YjgaEqynBhAQosNmDkh5fHWhrcRcWBqCYdbBeZ6XeFRG3Q9Q5JbnmJAUyjVJVV52rpMuLhQhLmSpQ5acznVttsuz', 'status': 1, 'fail_count': 0, 'created_at': 1544161168.7365992, 'environment': 'PRO'}] (Background on this error at: http://sqlalche.me/e/gkpj)
2018-12-07 05:39:29,312 reveal_service.py[line:144] ERROR 〓REVEAL〓 房间新建后第一次开奖，且无人下注 开奖失败 roomid=13 (pymysql.err.IntegrityError) (1062, "Duplicate entry '13-2' for key 'uix_id_name'") [SQL: 'INSERT INTO room_seed (room_id, game_id, house_seed_hash, house_seed, expire_timestamp, signature, status, fail_count, created_at, environment) VALUES (%(room_id)s, %(game_id)s, %(house_seed_hash)s, %(house_seed)s, %(expire_timestamp)s, %(signature)s, %(status)s, %(fail_count)s, %(created_at)s, %(environment)s)'] [parameters: {'room_id': 13, 'game_id': 2, 'house_seed_hash': 'db7819179f01c2b48ed6ffc54d145681f452499c69a25c50b47ffc5f244992ba', 'house_seed': '3c9116291b5e7526f3e91f21833e07b8cdfec28356c77d2f0c1f8c4665ed1c92', 'expire_timestamp': 1544161288, 'signature': 'SIG_K1_Kcprh7vQRkKEhX43HNqaihW36FXghLSP6q1n4SudnU1TkhNEpVhFguhmu5kupekQ1BqcpJTw9dp3i85eXe6JPAc293YCkm', 'status': 1, 'fail_count': 0, 'created_at': 1544161169.2566843, 'environment': 'PRO'}] (Background on this error at: http://sqlalche.me/e/gkpj)
2018-12-07 05:39:29,597 reveal_service.py[line:144] ERROR 〓REVEAL〓 房间新建后第一次开奖，且无人下注 开奖失败 roomid=13 (pymysql.err.IntegrityError) (1062, "Duplicate entry '13-2' for key 'uix_id_name'") [SQL: 'INSERT INTO room_seed (room_id, game_id, house_seed_hash, house_seed, expire_timestamp, signature, status, fail_count, created_at, environment) VALUES (%(room_id)s, %(game_id)s, %(house_seed_hash)s, %(house_seed)s, %(expire_timestamp)s, %(signature)s, %(status)s, %(fail_count)s, %(created_at)s, %(environment)s)'] [parameters: {'room_id': 13, 'game_id': 2, 'house_seed_hash': 'ada3fd3854ebc3bec75377b8bd1e6ed0d1ccb3bf2f4d345619c0f1c75b39d913', 'house_seed': '778e319ce25b69fca5971cfbb859b9b3e90d248dc4713cc226b176c494b754e5', 'expire_timestamp': 1544161288, 'signature': 'SIG_K1_K4oMVvVZFnQgqyADNm5QAnLJ3gfez2cvYraSQLASvVtPC5yBP3opRN16MQkB9RztAX1seqDd4NcVUqGzBrRNV12Nvgso5X', 'status': 1, 'fail_count': 0, 'created_at': 1544161169.5933113, 'environment': 'PRO'}] (Background on this error at: http://sqlalche.me/e/gkpj)
2018-12-07 05:40:56,184 connector.py[line:28] ERROR invalid room status roomid=14 gameid=1 异常已被处理
2018-12-07 05:40:56,286 connector.py[line:28] ERROR invalid room status roomid=14 gameid=1 异常已被处理
2018-12-07 05:40:56,294 connector.py[line:28] ERROR invalid room status roomid=14 gameid=1 异常已被处理
2018-12-07 05:40:56,909 reveal_service.py[line:144] ERROR 〓REVEAL〓 房间新建后第一次开奖，且无人下注 开奖失败 roomid=14 (pymysql.err.IntegrityError) (1062, "Duplicate entry '14-2' for key 'uix_id_name'") [SQL: 'INSERT INTO room_seed (room_id, game_id, house_seed_hash, house_seed, expire_timestamp, signature, status, fail_count, created_at, environment) VALUES (%(room_id)s, %(game_id)s, %(house_seed_hash)s, %(house_seed)s, %(expire_timestamp)s, %(signature)s, %(status)s, %(fail_count)s, %(created_at)s, %(environment)s)'] [parameters: {'room_id': 14, 'game_id': 2, 'house_seed_hash': '94e1e65c47a6ca0ffaec54fe7230326f4f7bc92e08cbeaec2a014076b86f3ffa', 'house_seed': '7bab884d499054ed938cc3f80784c2f9c97c4eac3e0b737d83959ecea6aab117', 'expire_timestamp': 1544161376, 'signature': 'SIG_K1_K5tWaHJGwHtAz7HTZ4hGUofcdEbd5uU34ZJYpSB1rEn7AC8y5mr4fsWFr5xNsoTZvYw4EMMTJNZvZoFTvMFAjCJ3M5fw9m', 'status': 1, 'fail_count': 0, 'created_at': 1544161256.8502667, 'environment': 'PRO'}] (Background on this error at: http://sqlalche.me/e/gkpj)
2018-12-07 05:40:57,281 reveal_service.py[line:144] ERROR 〓REVEAL〓 房间新建后第一次开奖，且无人下注 开奖失败 roomid=14 (pymysql.err.IntegrityError) (1062, "Duplicate entry '14-2' for key 'uix_id_name'") [SQL: 'INSERT INTO room_seed (room_id, game_id, house_seed_hash, house_seed, expire_timestamp, signature, status, fail_count, created_at, environment) VALUES (%(room_id)s, %(game_id)s, %(house_seed_hash)s, %(house_seed)s, %(expire_timestamp)s, %(signature)s, %(status)s, %(fail_count)s, %(created_at)s, %(environment)s)'] [parameters: {'room_id': 14, 'game_id': 2, 'house_seed_hash': 'd05ec450225cac0d69745cfbfe58359a3b6259b39984ad7e3899eaff752713e0', 'house_seed': '3e085a6dea1115653114326ccbf62f78be836c44973c850e4cb76bcf49ca6ca1', 'expire_timestamp': 1544161376, 'signature': 'SIG_K1_KkajRQprisBu18xYEfsTeLZ7CwBC4Mt8hTJp6xhH2GNbxbUVFB9GDdtAeTfYjz1D98DBkcsBntwt2xZSVYV8PLMAd82yXT', 'status': 1, 'fail_count': 0, 'created_at': 1544161257.1961954, 'environment': 'PRO'}] (Background on this error at: http://sqlalche.me/e/gkpj)
2018-12-07 05:40:57,447 reveal_service.py[line:144] ERROR 〓REVEAL〓 房间新建后第一次开奖，且无人下注 开奖失败 roomid=14 (pymysql.err.IntegrityError) (1062, "Duplicate entry '14-2' for key 'uix_id_name'") [SQL: 'INSERT INTO room_seed (room_id, game_id, house_seed_hash, house_seed, expire_timestamp, signature, status, fail_count, created_at, environment) VALUES (%(room_id)s, %(game_id)s, %(house_seed_hash)s, %(house_seed)s, %(expire_timestamp)s, %(signature)s, %(status)s, %(fail_count)s, %(created_at)s, %(environment)s)'] [parameters: {'room_id': 14, 'game_id': 2, 'house_seed_hash': '0abbe8fe79895d0adf276c15dc6cd1c0deb2aeade3329f3ca1578c468a57ec6d', 'house_seed': '74ceb26e6a2974a0c4a1162fe8b8e00f7f78a5a8bb9fcd07cdfa2b951493ff89', 'expire_timestamp': 1544161376, 'signature': 'SIG_K1_KaMeHfQYdP8VBzsWqS5HB8x8VrSaqAywtjwJcoD9g5s9cW4TQnGUnVNExPW4UizkRre6qSYXkrDcET2Hgn1zTLw4YeYvpR', 'status': 1, 'fail_count': 0, 'created_at': 1544161257.4429693, 'environment': 'PRO'}] (Background on this error at: http://sqlalche.me/e/gkpj)
2018-12-07 05:42:03,630 connector.py[line:28] ERROR invalid room status roomid=15 gameid=1 异常已被处理
2018-12-07 05:42:03,697 connector.py[line:28] ERROR invalid room status roomid=15 gameid=1 异常已被处理
2018-12-07 05:42:03,871 connector.py[line:28] ERROR invalid room status roomid=15 gameid=1 异常已被处理
2018-12-07 05:42:04,229 connector.py[line:28] ERROR invalid room status roomid=15 gameid=1 异常已被处理
2018-12-07 05:42:05,100 connector.py[line:28] ERROR invalid room status roomid=15 gameid=1 异常已被处理
2018-12-07 05:42:05,123 reveal_service.py[line:144] ERROR 〓REVEAL〓 房间新建后第一次开奖，且无人下注 开奖失败 roomid=15 (pymysql.err.IntegrityError) (1062, "Duplicate entry '15-2' for key 'uix_id_name'") [SQL: 'INSERT INTO room_seed (room_id, game_id, house_seed_hash, house_seed, expire_timestamp, signature, status, fail_count, created_at, environment) VALUES (%(room_id)s, %(game_id)s, %(house_seed_hash)s, %(house_seed)s, %(expire_timestamp)s, %(signature)s, %(status)s, %(fail_count)s, %(created_at)s, %(environment)s)'] [parameters: {'room_id': 15, 'game_id': 2, 'house_seed_hash': '49bfac1ed9b18e9b27a91b09dd929e1e097d6edd282dae81f581976c81c58bce', 'house_seed': '670445526d782e2423cf886055fcb6650ae54c2ddbc43c11090ddad9f90fdae3', 'expire_timestamp': 1544161443, 'signature': 'SIG_K1_KBRUT8uWpn2iyeD5jAuyv7vfDqtExuEd1Y7w9RQVyNegvCq2NNbWSVRTmEx4nPDA52jcAMbEMz8B66YYkKEMwLSxuXsDRP', 'status': 1, 'fail_count': 0, 'created_at': 1544161324.8688653, 'environment': 'PRO'}] (Background on this error at: http://sqlalche.me/e/gkpj)
2018-12-07 05:42:05,519 reveal_service.py[line:144] ERROR 〓REVEAL〓 房间新建后第一次开奖，且无人下注 开奖失败 roomid=15 (pymysql.err.IntegrityError) (1062, "Duplicate entry '15-2' for key 'uix_id_name'") [SQL: 'INSERT INTO room_seed (room_id, game_id, house_seed_hash, house_seed, expire_timestamp, signature, status, fail_count, created_at, environment) VALUES (%(room_id)s, %(game_id)s, %(house_seed_hash)s, %(house_seed)s, %(expire_timestamp)s, %(signature)s, %(status)s, %(fail_count)s, %(created_at)s, %(environment)s)'] [parameters: {'room_id': 15, 'game_id': 2, 'house_seed_hash': 'aac4bb86904ee27e8bc775cb9e56b4f6bc9d4498ab40bb6cbb4c1d2cd51a53d5', 'house_seed': 'deadf197b4072cc4a3cf08894d46931218b404ee64daf9abb312379d0feff5ff', 'expire_timestamp': 1544161443, 'signature': 'SIG_K1_Kd4npmqiyJYjvBexWLSyLJYw6QJQgZGgphypq6vqsTPme7rzpm8u3UBh8qdSvc7gTsMJ97LcbWjR5zGHXHNnmPLgt8BViW', 'status': 1, 'fail_count': 0, 'created_at': 1544161325.1573083, 'environment': 'PRO'}] (Background on this error at: http://sqlalche.me/e/gkpj)
2018-12-07 05:42:05,919 reveal_service.py[line:144] ERROR 〓REVEAL〓 房间新建后第一次开奖，且无人下注 开奖失败 roomid=15 (pymysql.err.IntegrityError) (1062, "Duplicate entry '15-2' for key 'uix_id_name'") [SQL: 'INSERT INTO room_seed (room_id, game_id, house_seed_hash, house_seed, expire_timestamp, signature, status, fail_count, created_at, environment) VALUES (%(room_id)s, %(game_id)s, %(house_seed_hash)s, %(house_seed)s, %(expire_timestamp)s, %(signature)s, %(status)s, %(fail_count)s, %(created_at)s, %(environment)s)'] [parameters: {'room_id': 15, 'game_id': 2, 'house_seed_hash': '6b1da4b7d11a59ace56dd43255c4792343d70ed90887717ce9fa00fc1f152c13', 'house_seed': '20cff1b788b8cbec5204f389d8524c7bc33cc6d9b6f22906a18b755b1c07bf2a', 'expire_timestamp': 1544161445, 'signature': 'SIG_K1_K81rEQJ4ryViiVviFNjyPhKcbzVGBa3R2XEbSfYHJ9cDSCdYgcutix94zjjUUbKujLsksVwL5RJyiGtZFCUZ1fZ3KUZxFh', 'status': 1, 'fail_count': 0, 'created_at': 1544161325.8637204, 'environment': 'PRO'}] (Background on this error at: http://sqlalche.me/e/gkpj)
2018-12-07 05:42:06,017 reveal_service.py[line:144] ERROR 〓REVEAL〓 房间新建后第一次开奖，且无人下注 开奖失败 roomid=15 (pymysql.err.IntegrityError) (1062, "Duplicate entry '15-2' for key 'uix_id_name'") [SQL: 'INSERT INTO room_seed (room_id, game_id, house_seed_hash, house_seed, expire_timestamp, signature, status, fail_count, created_at, environment) VALUES (%(room_id)s, %(game_id)s, %(house_seed_hash)s, %(house_seed)s, %(expire_timestamp)s, %(signature)s, %(status)s, %(fail_count)s, %(created_at)s, %(environment)s)'] [parameters: {'room_id': 15, 'game_id': 2, 'house_seed_hash': 'bb65d83718553e8440e365400d7415b0da3d7afc71b384dd830ef11095200095', 'house_seed': '871a1e218a006b9b5e1733e4ae3a680a6427564575978b4f609931726fcef22f', 'expire_timestamp': 1544161444, 'signature': 'SIG_K1_KBBGCdFGuEJaFBNJky1Gx78KjHtDMnRpr3iyKkd1WKhZ6CRaZbEHYnXspp7mmmx23Qyt1LvkgQJHKyDeQt2dBWDiG4vyZE', 'status': 1, 'fail_count': 0, 'created_at': 1544161325.986221, 'environment': 'PRO'}] (Background on this error at: http://sqlalche.me/e/gkpj)
2018-12-07 05:42:06,028 reveal_service.py[line:144] ERROR 〓REVEAL〓 房间新建后第一次开奖，且无人下注 开奖失败 roomid=15 (pymysql.err.IntegrityError) (1062, "Duplicate entry '15-2' for key 'uix_id_name'") [SQL: 'INSERT INTO room_seed (room_id, game_id, house_seed_hash, house_seed, expire_timestamp, signature, status, fail_count, created_at, environment) VALUES (%(room_id)s, %(game_id)s, %(house_seed_hash)s, %(house_seed)s, %(expire_timestamp)s, %(signature)s, %(status)s, %(fail_count)s, %(created_at)s, %(environment)s)'] [parameters: {'room_id': 15, 'game_id': 2, 'house_seed_hash': '8bed4b7fb858537e34f12069db939135be35c4dbbcea03a7b5f58dfc88a3b00c', 'house_seed': 'd13e0df077283eb86ece7547f3bfd43e360288ebeaa525620c9abf14ccbf4291', 'expire_timestamp': 1544161443, 'signature': 'SIG_K1_KYNUMKpPWrT7sDSWN7dun1gHLMRVMVVaYokbTqtzEArptEjBLr2LP3Gg2QfoDUi3jfcEHmQEbGyKcaq37aancpA5nNRF7W', 'status': 1, 'fail_count': 0, 'created_at': 1544161325.998948, 'environment': 'PRO'}] (Background on this error at: http://sqlalche.me/e/gkpj)
2018-12-07 05:42:28,311 connector.py[line:28] ERROR invalid room status roomid=16 gameid=1 异常已被处理
2018-12-07 05:42:28,546 connector.py[line:28] ERROR invalid room status roomid=16 gameid=1 异常已被处理
2018-12-07 05:42:28,995 connector.py[line:28] ERROR invalid room status roomid=16 gameid=1 异常已被处理
2018-12-07 05:42:29,018 connector.py[line:28] ERROR invalid room status roomid=16 gameid=1 异常已被处理
2018-12-07 05:42:29,342 reveal_service.py[line:144] ERROR 〓REVEAL〓 房间新建后第一次开奖，且无人下注 开奖失败 roomid=16 (pymysql.err.IntegrityError) (1062, "Duplicate entry '16-2' for key 'uix_id_name'") [SQL: 'INSERT INTO room_seed (room_id, game_id, house_seed_hash, house_seed, expire_timestamp, signature, status, fail_count, created_at, environment) VALUES (%(room_id)s, %(game_id)s, %(house_seed_hash)s, %(house_seed)s, %(expire_timestamp)s, %(signature)s, %(status)s, %(fail_count)s, %(created_at)s, %(environment)s)'] [parameters: {'room_id': 16, 'game_id': 2, 'house_seed_hash': 'ebe5f98643610d8f07ea12985525cdd2b2b75fc7587ba96f8dcb5408deca30d5', 'house_seed': '0acc9c0538682e5d7eec2649941eb44ffcff02e16ac4300c751b8343b6aea798', 'expire_timestamp': 1544161468, 'signature': 'SIG_K1_JyJgjge2ZCRM29WWV4WLz7YADKuxGPH9SfVFmzuTTAdDS3SKjwbVnG6Q9nHumUP6JccKgDhyXsqS3XqsnM4wvbK2gsRoWU', 'status': 1, 'fail_count': 0, 'created_at': 1544161349.2573497, 'environment': 'PRO'}] (Background on this error at: http://sqlalche.me/e/gkpj)
2018-12-07 05:42:30,410 reveal_service.py[line:144] ERROR 〓REVEAL〓 房间新建后第一次开奖，且无人下注 开奖失败 roomid=16 (pymysql.err.IntegrityError) (1062, "Duplicate entry '16-2' for key 'uix_id_name'") [SQL: 'INSERT INTO room_seed (room_id, game_id, house_seed_hash, house_seed, expire_timestamp, signature, status, fail_count, created_at, environment) VALUES (%(room_id)s, %(game_id)s, %(house_seed_hash)s, %(house_seed)s, %(expire_timestamp)s, %(signature)s, %(status)s, %(fail_count)s, %(created_at)s, %(environment)s)'] [parameters: {'room_id': 16, 'game_id': 2, 'house_seed_hash': 'afe9048f96327f98ca7be10ca040e35639f186167d5b1c07f7e735a9ef869a37', 'house_seed': 'c3e5c1a42c39be7cd6a718f298d01b40b75cff0af903f5b2ba166f98f47f60c4', 'expire_timestamp': 1544161469, 'signature': 'SIG_K1_JzvUTJ18mTZFva45kEK6YGsBqKc7UCRJiPKWYt2L2Jm3D4tV9enuHSytHznMBA8hoP387UNrQMf32i6jHUSNtUEAmXKFXC', 'status': 1, 'fail_count': 0, 'created_at': 1544161350.3586175, 'environment': 'PRO'}] (Background on this error at: http://sqlalche.me/e/gkpj)
2018-12-07 05:42:30,481 reveal_service.py[line:144] ERROR 〓REVEAL〓 房间新建后第一次开奖，且无人下注 开奖失败 roomid=16 (pymysql.err.IntegrityError) (1062, "Duplicate entry '16-2' for key 'uix_id_name'") [SQL: 'INSERT INTO room_seed (room_id, game_id, house_seed_hash, house_seed, expire_timestamp, signature, status, fail_count, created_at, environment) VALUES (%(room_id)s, %(game_id)s, %(house_seed_hash)s, %(house_seed)s, %(expire_timestamp)s, %(signature)s, %(status)s, %(fail_count)s, %(created_at)s, %(environment)s)'] [parameters: {'room_id': 16, 'game_id': 2, 'house_seed_hash': 'e9e438183d3c4fe9ee5f68f300e5ebc256cd465da73fdd9fb96fdfefd5e5ad62', 'house_seed': '5028fe6608bb087038985797e4d669f95ed342f5d6e66a9c9aa1d62bbcb5d6ab', 'expire_timestamp': 1544161468, 'signature': 'SIG_K1_Kkbf6aBq4vq3LFWidHoD6Yn5g9zL5p5xjDKaEWD6A3U8aynvrotommHFKzKNCmVwf9VYrQs5ok1vjVUneeaYAAEgsoQEUS', 'status': 1, 'fail_count': 0, 'created_at': 1544161350.405021, 'environment': 'PRO'}] (Background on this error at: http://sqlalche.me/e/gkpj)
2018-12-07 05:42:30,765 reveal_service.py[line:144] ERROR 〓REVEAL〓 房间新建后第一次开奖，且无人下注 开奖失败 roomid=16 (pymysql.err.IntegrityError) (1062, "Duplicate entry '16-2' for key 'uix_id_name'") [SQL: 'INSERT INTO room_seed (room_id, game_id, house_seed_hash, house_seed, expire_timestamp, signature, status, fail_count, created_at, environment) VALUES (%(room_id)s, %(game_id)s, %(house_seed_hash)s, %(house_seed)s, %(expire_timestamp)s, %(signature)s, %(status)s, %(fail_count)s, %(created_at)s, %(environment)s)'] [parameters: {'room_id': 16, 'game_id': 2, 'house_seed_hash': '7a9053046de4ba57346c82ea4370b82bb0e20f0ec989b8997890be3ba81d1eb4', 'house_seed': 'c96a12aef60cd930d04d11e830bfc147164f8806a25c57712abb626fceb3d804', 'expire_timestamp': 1544161469, 'signature': 'SIG_K1_KY1BFXU5us7LMU4nXYE6TVSimaWYrP79FCaCtYdQmMAzbUQ8K3DW9ca4UBvzkabYVy1wdek4rngStaWgaokExPFTCeRpXx', 'status': 1, 'fail_count': 0, 'created_at': 1544161350.7316625, 'environment': 'PRO'}] (Background on this error at: http://sqlalche.me/e/gkpj)
2018-12-07 05:42:31,024 reveal_service.py[line:144] ERROR 〓REVEAL〓 房间新建后第一次开奖，且无人下注 开奖失败 roomid=16 (pymysql.err.IntegrityError) (1062, "Duplicate entry '16-2' for key 'uix_id_name'") [SQL: 'INSERT INTO room_seed (room_id, game_id, house_seed_hash, house_seed, expire_timestamp, signature, status, fail_count, created_at, environment) VALUES (%(room_id)s, %(game_id)s, %(house_seed_hash)s, %(house_seed)s, %(expire_timestamp)s, %(signature)s, %(status)s, %(fail_count)s, %(created_at)s, %(environment)s)'] [parameters: {'room_id': 16, 'game_id': 2, 'house_seed_hash': '85b6d5a5f39932af5d7ad95435f30486b6201376e529ac292a80bdd365e6a590', 'house_seed': 'cefaf104935f2c5a6cfc5684b223fda9964ddf3bfa7c762c2c55573c10e31a64', 'expire_timestamp': 1544161469, 'signature': 'SIG_K1_KbJ73ayrLJDvQwW9JCVFLH1q2APGK5vw2AXhi1zhecxHxmUAGmaPTqxrYFvfUbqeh5jQFeqVeo8Hv3daXZEMmb3RJB1njs', 'status': 1, 'fail_count': 0, 'created_at': 1544161351.0198648, 'environment': 'PRO'}] (Background on this error at: http://sqlalche.me/e/gkpj)
2018-12-07 05:44:08,507 reveal_service.py[line:144] ERROR 〓REVEAL〓 房间新建后第一次开奖，且无人下注 开奖失败 roomid=17 b'\x1b[31mError 3050003: eosio_assert_message assertion failure\x1b[0m\n\x1b[33mError Details:\nassertion failure with message: 100016 room not found\npending console output: \x1b[0m\n'
2018-12-07 05:44:08,568 reveal_service.py[line:144] ERROR 〓REVEAL〓 房间新建后第一次开奖，且无人下注 开奖失败 roomid=17 b'\x1b[31mError 3050003: eosio_assert_message assertion failure\x1b[0m\n\x1b[33mError Details:\nassertion failure with message: 100016 room not found\npending console output: \x1b[0m\n'
2018-12-07 05:44:08,936 reveal_service.py[line:144] ERROR 〓REVEAL〓 房间新建后第一次开奖，且无人下注 开奖失败 roomid=17 b'\x1b[31mError 3050003: eosio_assert_message assertion failure\x1b[0m\n\x1b[33mError Details:\nassertion failure with message: 100016 room not found\npending console output: \x1b[0m\n'
2018-12-07 05:44:08,979 reveal_service.py[line:144] ERROR 〓REVEAL〓 房间新建后第一次开奖，且无人下注 开奖失败 roomid=17 b'\x1b[31mError 3050003: eosio_assert_message assertion failure\x1b[0m\n\x1b[33mError Details:\nassertion failure with message: 100016 room not found\npending console output: \x1b[0m\n'
2018-12-07 05:44:09,327 reveal_service.py[line:144] ERROR 〓REVEAL〓 房间新建后第一次开奖，且无人下注 开奖失败 roomid=17 b'\x1b[31mError 3050003: eosio_assert_message assertion failure\x1b[0m\n\x1b[33mError Details:\nassertion failure with message: 100016 room not found\npending console output: \x1b[0m\n'
2018-12-07 06:12:25,635 reveal_service.py[line:128] ERROR [async_call_sub] 异常，重试1次 id=24963 roomid=16 game_id=34 =b'\x1b[31mError 3080001: Account using more than allotted RAM usage\x1b[0m\n\x1b[33mError Details:\naccount ffgamebacara has insufficient ram; needs 2402858 bytes has 2402211 bytes\x1b[0m\n'
2018-12-07 06:12:27,438 reveal_service.py[line:128] ERROR [async_call_sub] 异常，重试2次 id=24963 roomid=16 game_id=34 =b'\x1b[31mError 3080001: Account using more than allotted RAM usage\x1b[0m\n\x1b[33mError Details:\naccount ffgamebacara has insufficient ram; needs 2402794 bytes has 2402211 bytes\x1b[0m\n'
2018-12-07 06:12:28,701 reveal_service.py[line:128] ERROR [async_call_sub] 异常，重试1次 id=24966 roomid=12 game_id=223 =b'\x1b[31mError 3080001: Account using more than allotted RAM usage\x1b[0m\n\x1b[33mError Details:\naccount ffgamebacara has insufficient ram; needs 2402661 bytes has 2402211 bytes\x1b[0m\n'
2018-12-07 06:12:29,255 reveal_service.py[line:128] ERROR [async_call_sub] 异常，重试3次 id=24963 roomid=16 game_id=34 =b'\x1b[31mError 3080001: Account using more than allotted RAM usage\x1b[0m\n\x1b[33mError Details:\naccount ffgamebacara has insufficient ram; needs 2402794 bytes has 2402211 bytes\x1b[0m\n'
2018-12-07 06:12:30,035 reveal_service.py[line:128] ERROR [async_call_sub] 异常，重试2次 id=24966 roomid=12 game_id=223 =b'\x1b[31mError 3080001: Account using more than allotted RAM usage\x1b[0m\n\x1b[33mError Details:\naccount ffgamebacara has insufficient ram; needs 2402661 bytes has 2402211 bytes\x1b[0m\n'
2018-12-07 06:12:33,372 reveal_service.py[line:128] ERROR [async_call_sub] 异常，重试3次 id=24966 roomid=12 game_id=223 =b'\x1b[31mError 3080001: Account using more than allotted RAM usage\x1b[0m\n\x1b[33mError Details:\naccount ffgamebacara has insufficient ram; needs 2402661 bytes has 2402211 bytes\x1b[0m\n'
2018-12-07 06:12:40,116 reveal_service.py[line:128] ERROR [async_call_sub] 异常，重试1次 id=24967 roomid=11 game_id=699 =b'\x1b[31mError 3080001: Account using more than allotted RAM usage\x1b[0m\n\x1b[33mError Details:\naccount ffgamebacara has insufficient ram; needs 2402298 bytes has 2402211 bytes\x1b[0m\n'
2018-12-07 06:12:41,923 reveal_service.py[line:128] ERROR [async_call_sub] 异常，重试2次 id=24967 roomid=11 game_id=699 =b'\x1b[31mError 3080001: Account using more than allotted RAM usage\x1b[0m\n\x1b[33mError Details:\naccount ffgamebacara has insufficient ram; needs 2402298 bytes has 2402211 bytes\x1b[0m\n'
2018-12-07 06:12:43,220 reveal_service.py[line:128] ERROR [async_call_sub] 异常，重试3次 id=24967 roomid=11 game_id=699 =b'\x1b[31mError 3080001: Account using more than allotted RAM usage\x1b[0m\n\x1b[33mError Details:\naccount ffgamebacara has insufficient ram; needs 2402298 bytes has 2402211 bytes\x1b[0m\n'
2018-12-07 06:13:18,290 reveal_service.py[line:128] ERROR [async_call_sub] 异常，重试1次 id=24970 roomid=8 game_id=1669 =b'\x1b[31mError 3080001: Account using more than allotted RAM usage\x1b[0m\n\x1b[33mError Details:\naccount ffgamebacara has insufficient ram; needs 2402264 bytes has 2402211 bytes\x1b[0m\n'
2018-12-07 06:13:19,573 reveal_service.py[line:128] ERROR [async_call_sub] 异常，重试2次 id=24970 roomid=8 game_id=1669 =b'\x1b[31mError 3080001: Account using more than allotted RAM usage\x1b[0m\n\x1b[33mError Details:\naccount ffgamebacara has insufficient ram; needs 2402538 bytes has 2402211 bytes\x1b[0m\n'
2018-12-07 06:13:21,869 reveal_service.py[line:128] ERROR [async_call_sub] 异常，重试3次 id=24970 roomid=8 game_id=1669 =b'\x1b[31mError 3080001: Account using more than allotted RAM usage\x1b[0m\n\x1b[33mError Details:\naccount ffgamebacara has insufficient ram; needs 2402538 bytes has 2402211 bytes\x1b[0m\n'
2018-12-07 06:13:51,109 reveal_service.py[line:128] ERROR [async_call_sub] 异常，重试1次 id=24972 roomid=1 game_id=2303 =b'\x1b[31mError 3080001: Account using more than allotted RAM usage\x1b[0m\n\x1b[33mError Details:\naccount ffgamebacara has insufficient ram; needs 2403039 bytes has 2402211 bytes\x1b[0m\n'
2018-12-07 06:13:52,999 reveal_service.py[line:128] ERROR [async_call_sub] 异常，重试2次 id=24972 roomid=1 game_id=2303 =b'\x1b[31mError 3080001: Account using more than allotted RAM usage\x1b[0m\n\x1b[33mError Details:\naccount ffgamebacara has insufficient ram; needs 2403039 bytes has 2402211 bytes\x1b[0m\n'
2018-12-07 06:13:55,288 reveal_service.py[line:128] ERROR [async_call_sub] 异常，重试3次 id=24972 roomid=1 game_id=2303 =b'\x1b[31mError 3080001: Account using more than allotted RAM usage\x1b[0m\n\x1b[33mError Details:\naccount ffgamebacara has insufficient ram; needs 2403039 bytes has 2402211 bytes\x1b[0m\n'
2018-12-07 06:17:19,181 seed_service.py[line:125] ERROR no seed data
2018-12-07 06:17:19,181 seed_service.py[line:44] ERROR get_seed 异常 =no seed data
2018-12-07 06:17:19,181 views.py[line:78] ERROR api get_seed 异常=no seed data
2018-12-07 06:37:54,641 reveal_service.py[line:128] ERROR [async_call_sub] 异常，重试1次 id=25139 roomid=18 game_id=60 =b'\x1b[31mError 3050003: eosio_assert_message assertion failure\x1b[0m\n\x1b[33mError Details:\nassertion failure with message: 100013 invalid room status\npending console output: \x1b[0m\n'
2018-12-07 06:54:01,042 reveal_service.py[line:128] ERROR [async_call_sub] 异常，重试1次 id=25267 roomid=16 game_id=77 =b'\x1b[31mError 3050003: eosio_assert_message assertion failure\x1b[0m\n\x1b[33mError Details:\nassertion failure with message: 100013 invalid room status\npending console output: \x1b[0m\n'
2018-12-07 06:54:01,306 reveal_service.py[line:128] ERROR [async_call_sub] 异常，重试1次 id=25268 roomid=6 game_id=2240 =b'\x1b[31mError 3050003: eosio_assert_message assertion failure\x1b[0m\n\x1b[33mError Details:\nassertion failure with message: 100013 invalid room status\npending console output: \x1b[0m\n'
2018-12-07 07:07:18,480 reveal_service.py[line:128] ERROR [async_call_sub] 异常，重试1次 id=25372 roomid=16 game_id=92 =b'\x1b[31mError 3050003: eosio_assert_message assertion failure\x1b[0m\n\x1b[33mError Details:\nassertion failure with message: 100013 invalid room status\npending console output: \x1b[0m\n'
2018-12-07 07:44:25,739 reveal_service.py[line:128] ERROR [async_call_sub] 异常，重试1次 id=25667 roomid=6 game_id=2297 =b'\x1b[31mError 3050003: eosio_assert_message assertion failure\x1b[0m\n\x1b[33mError Details:\nassertion failure with message: 100013 invalid room status\npending console output: \x1b[0m\n'
2018-12-07 08:00:09,542 reveal_service.py[line:128] ERROR [async_call_sub] 异常，重试1次 id=25787 roomid=11 game_id=817 =b'\x1b[31mError 3050003: eosio_assert_message assertion failure\x1b[0m\n\x1b[33mError Details:\nassertion failure with message: 100013 invalid room status\npending console output: \x1b[0m\n'
2018-12-07 08:00:58,127 reveal_service.py[line:128] ERROR [async_call_sub] 异常，重试1次 id=25793 roomid=18 game_id=154 =b'\x1b[31mError 3040005: Expired Transaction\x1b[0m\n\x1b[32mPlease increase the expiration time of your transaction!\x1b[0m\n\x1b[33mError Details:\nexpired transaction e74fd661bbd4a2df2677f274c616b69f60ff187d79d4651e4e8028c9e8eb9871\x1b[0m\n'
2018-12-07 08:01:30,257 reveal_service.py[line:128] ERROR [async_call_sub] 异常，重试2次 id=25793 roomid=18 game_id=154 =b'error 2018-12-07T08:01:30.256 thread-0  main.cpp:3151                 main                 ] Failed with error: Parse Error (4)\nUnexpected char \'60\' in ""\n\n\n'
2018-12-07 08:01:39,319 reveal_service.py[line:128] ERROR [async_call_sub] 异常，重试1次 id=25796 roomid=16 game_id=153 =b'error 2018-12-07T08:01:39.317 thread-0  main.cpp:3151                 main                 ] Failed with error: Parse Error (4)\nUnexpected char \'60\' in ""\n\n\n'
2018-12-07 08:02:02,042 reveal_service.py[line:128] ERROR [async_call_sub] 异常，重试3次 id=25793 roomid=18 game_id=154 =b'error 2018-12-07T08:02:02.041 thread-0  main.cpp:3151                 main                 ] Failed with error: Parse Error (4)\nUnexpected char \'60\' in ""\n\n\n'
2018-12-07 08:02:02,123 reveal_service.py[line:128] ERROR [async_call_sub] 异常，重试1次 id=25801 roomid=1 game_id=2418 =b'\x1b[31mError 3040005: Expired Transaction\x1b[0m\n\x1b[32mPlease increase the expiration time of your transaction!\x1b[0m\n\x1b[33mError Details:\nexpired transaction 474ab30ddbc43eb04b572d5270a91ed9a9e1c03741fb26867d3460589cda0092\x1b[0m\n'
2018-12-07 08:02:04,777 reveal_service.py[line:128] ERROR [async_call_sub] 异常，重试2次 id=25801 roomid=1 game_id=2418 =b'\x1b[31mError 3040005: Expired Transaction\x1b[0m\n\x1b[32mPlease increase the expiration time of your transaction!\x1b[0m\n\x1b[33mError Details:\nexpired transaction 474ab30ddbc43eb04b572d5270a91ed9a9e1c03741fb26867d3460589cda0092\x1b[0m\n'
2018-12-07 08:02:37,521 reveal_service.py[line:128] ERROR [async_call_sub] 异常，重试3次 id=25801 roomid=1 game_id=2418 =b'error 2018-12-07T08:02:37.520 thread-0  main.cpp:3151                 main                 ] Failed with error: Parse Error (4)\nUnexpected char \'60\' in ""\n\n\n'
2018-12-07 08:02:41,600 reveal_service.py[line:128] ERROR [async_call_sub] 异常，重试1次 id=25803 roomid=12 game_id=343 =b'error 2018-12-07T08:02:41.599 thread-0  main.cpp:3151                 main                 ] Failed with error: Parse Error (4)\nUnexpected char \'60\' in ""\n\n\n'
2018-12-07 08:02:51,229 reveal_service.py[line:128] ERROR [async_call_sub] 异常，重试1次 id=25804 roomid=8 game_id=1789 =b'error 2018-12-07T08:02:51.228 thread-0  main.cpp:3151                 main                 ] Failed with error: Parse Error (4)\nUnexpected char \'60\' in ""\n\n\n'
2018-12-07 08:02:53,548 reveal_service.py[line:128] ERROR [async_call_sub] 异常，重试2次 id=25804 roomid=8 game_id=1789 =b'\x1b[31mError 3040005: Expired Transaction\x1b[0m\n\x1b[32mPlease increase the expiration time of your transaction!\x1b[0m\n\x1b[33mError Details:\nexpired transaction 7d3d105ca75b4937583d7886221bbae93785586c07de214e8987415523fea048\x1b[0m\n'
2018-12-07 08:02:58,013 reveal_service.py[line:128] ERROR [async_call_sub] 异常，重试1次 id=25801 roomid=1 game_id=2418 =b'\x1b[31mError 3040005: Expired Transaction\x1b[0m\n\x1b[32mPlease increase the expiration time of your transaction!\x1b[0m\n\x1b[33mError Details:\nexpired transaction 474ab30ddbc43eb04b572d5270a91ed9a9e1c03741fb26867d3460589cda0092\x1b[0m\n'
2018-12-07 08:03:00,534 reveal_service.py[line:128] ERROR [async_call_sub] 异常，重试2次 id=25801 roomid=1 game_id=2418 =b"\x1b[31mError 3040007: Invalid Reference Block\x1b[0m\n\x1b[32mEnsure that the reference block exist in the blockchain!\x1b[0m\n\x1b[33mError Details:\nTransaction's reference block did not match. Is this transaction from a different fork?\x1b[0m\n"
2018-12-07 08:03:02,865 reveal_service.py[line:128] ERROR [async_call_sub] 异常，重试3次 id=25801 roomid=1 game_id=2418 =b"\x1b[31mError 3040007: Invalid Reference Block\x1b[0m\n\x1b[32mEnsure that the reference block exist in the blockchain!\x1b[0m\n\x1b[33mError Details:\nTransaction's reference block did not match. Is this transaction from a different fork?\x1b[0m\n"
2018-12-07 08:03:03,663 reveal_service.py[line:128] ERROR [async_call_sub] 异常，重试1次 id=25805 roomid=16 game_id=154 =b'error 2018-12-07T08:03:03.662 thread-0  main.cpp:3151                 main                 ] Failed with error: Parse Error (4)\nUnexpected char \'60\' in ""\n\n\n'
2018-12-07 08:03:13,071 reveal_service.py[line:128] ERROR [async_call_sub] 异常，重试2次 id=25803 roomid=12 game_id=343 =b'error 2018-12-07T08:03:13.068 thread-0  main.cpp:3151                 main                 ] Failed with error: Parse Error (4)\nUnexpected char \'60\' in ""\n\n\n'
2018-12-07 08:03:15,721 reveal_service.py[line:128] ERROR [async_call_sub] 异常，重试3次 id=25803 roomid=12 game_id=343 =b'\x1b[31mError 3040005: Expired Transaction\x1b[0m\n\x1b[32mPlease increase the expiration time of your transaction!\x1b[0m\n\x1b[33mError Details:\nexpired transaction fe33be9aaae152054924ae3492c67c4ad83bb9112de71cc8b4245d01b4aaa7c7\x1b[0m\n'
2018-12-07 08:03:28,138 reveal_service.py[line:128] ERROR [async_call_sub] 异常，重试1次 id=25793 roomid=18 game_id=154 =b'error 2018-12-07T08:03:28.136 thread-0  main.cpp:3151                 main                 ] Failed with error: Parse Error (4)\nUnexpected char \'60\' in ""\n\n\n'
2018-12-07 08:03:42,945 reveal_service.py[line:128] ERROR [async_call_sub] 异常，重试1次 id=25808 roomid=11 game_id=821 =b"\x1b[31mError 3040007: Invalid Reference Block\x1b[0m\n\x1b[32mEnsure that the reference block exist in the blockchain!\x1b[0m\n\x1b[33mError Details:\nTransaction's reference block did not match. Is this transaction from a different fork?\x1b[0m\n"
2018-12-07 08:03:44,942 reveal_service.py[line:128] ERROR [async_call_sub] 异常，重试2次 id=25808 roomid=11 game_id=821 =b"\x1b[31mError 3040007: Invalid Reference Block\x1b[0m\n\x1b[32mEnsure that the reference block exist in the blockchain!\x1b[0m\n\x1b[33mError Details:\nTransaction's reference block did not match. Is this transaction from a different fork?\x1b[0m\n"
2018-12-07 08:03:47,542 reveal_service.py[line:128] ERROR [async_call_sub] 异常，重试3次 id=25808 roomid=11 game_id=821 =b"\x1b[31mError 3040007: Invalid Reference Block\x1b[0m\n\x1b[32mEnsure that the reference block exist in the blockchain!\x1b[0m\n\x1b[33mError Details:\nTransaction's reference block did not match. Is this transaction from a different fork?\x1b[0m\n"
2018-12-07 08:03:50,621 reveal_service.py[line:128] ERROR [async_call_sub] 异常，重试1次 id=25810 roomid=6 game_id=2319 =b'\x1b[31mError 3040005: Expired Transaction\x1b[0m\n\x1b[32mPlease increase the expiration time of your transaction!\x1b[0m\n\x1b[33mError Details:\nexpired transaction 1a831c23ed05f519172278aaf8690370d38fee99774b76823308d26a5d4313b2\x1b[0m\n'
2018-12-07 08:03:53,568 reveal_service.py[line:128] ERROR [async_call_sub] 异常，重试2次 id=25810 roomid=6 game_id=2319 =b"\x1b[31mError 3040007: Invalid Reference Block\x1b[0m\n\x1b[32mEnsure that the reference block exist in the blockchain!\x1b[0m\n\x1b[33mError Details:\nTransaction's reference block did not match. Is this transaction from a different fork?\x1b[0m\n"
2018-12-07 08:03:56,034 reveal_service.py[line:128] ERROR [async_call_sub] 异常，重试3次 id=25810 roomid=6 game_id=2319 =b'\x1b[31mError 3040005: Expired Transaction\x1b[0m\n\x1b[32mPlease increase the expiration time of your transaction!\x1b[0m\n\x1b[33mError Details:\nexpired transaction 1a831c23ed05f519172278aaf8690370d38fee99774b76823308d26a5d4313b2\x1b[0m\n'
2018-12-07 08:04:20,297 reveal_service.py[line:128] ERROR [async_call_sub] 异常，重试1次 id=25801 roomid=1 game_id=2418 =b"\x1b[31mError 3040007: Invalid Reference Block\x1b[0m\n\x1b[32mEnsure that the reference block exist in the blockchain!\x1b[0m\n\x1b[33mError Details:\nTransaction's reference block did not match. Is this transaction from a different fork?\x1b[0m\n"
2018-12-07 08:04:20,683 reveal_service.py[line:128] ERROR [async_call_sub] 异常，重试1次 id=25803 roomid=12 game_id=343 =b'\x1b[31mError 3040005: Expired Transaction\x1b[0m\n\x1b[32mPlease increase the expiration time of your transaction!\x1b[0m\n\x1b[33mError Details:\nexpired transaction fe33be9aaae152054924ae3492c67c4ad83bb9112de71cc8b4245d01b4aaa7c7\x1b[0m\n'
2018-12-07 08:04:22,282 reveal_service.py[line:128] ERROR [async_call_sub] 异常，重试2次 id=25801 roomid=1 game_id=2418 =b'\x1b[31mError 3040005: Expired Transaction\x1b[0m\n\x1b[32mPlease increase the expiration time of your transaction!\x1b[0m\n\x1b[33mError Details:\nexpired transaction 474ab30ddbc43eb04b572d5270a91ed9a9e1c03741fb26867d3460589cda0092\x1b[0m\n'
2018-12-07 08:04:22,291 reveal_service.py[line:128] ERROR [async_call_sub] 异常，重试2次 id=25803 roomid=12 game_id=343 =b'\x1b[31mError 3040005: Expired Transaction\x1b[0m\n\x1b[32mPlease increase the expiration time of your transaction!\x1b[0m\n\x1b[33mError Details:\nexpired transaction fe33be9aaae152054924ae3492c67c4ad83bb9112de71cc8b4245d01b4aaa7c7\x1b[0m\n'
2018-12-07 08:04:22,501 reveal_service.py[line:128] ERROR [async_call_sub] 异常，重试1次 id=25812 roomid=18 game_id=155 =b"\x1b[31mError 3040007: Invalid Reference Block\x1b[0m\n\x1b[32mEnsure that the reference block exist in the blockchain!\x1b[0m\n\x1b[33mError Details:\nTransaction's reference block did not match. Is this transaction from a different fork?\x1b[0m\n"
2018-12-07 08:04:52,843 reveal_service.py[line:128] ERROR [async_call_sub] 异常，重试1次 id=25814 roomid=16 game_id=156 =b"\x1b[31mError 3040007: Invalid Reference Block\x1b[0m\n\x1b[32mEnsure that the reference block exist in the blockchain!\x1b[0m\n\x1b[33mError Details:\nTransaction's reference block did not match. Is this transaction from a different fork?\x1b[0m\n"
2018-12-07 08:04:54,968 reveal_service.py[line:128] ERROR [async_call_sub] 异常，重试2次 id=25814 roomid=16 game_id=156 =b"\x1b[31mError 3040007: Invalid Reference Block\x1b[0m\n\x1b[32mEnsure that the reference block exist in the blockchain!\x1b[0m\n\x1b[33mError Details:\nTransaction's reference block did not match. Is this transaction from a different fork?\x1b[0m\n"
2018-12-07 08:05:11,495 reveal_service.py[line:128] ERROR [async_call_sub] 异常，重试1次 id=25813 roomid=8 game_id=1791 =b'error 2018-12-07T08:05:11.494 thread-0  main.cpp:3151                 main                 ] Failed with error: Parse Error (4)\nUnexpected char \'60\' in ""\n\n\n'
2018-12-07 08:05:13,546 reveal_service.py[line:128] ERROR [async_call_sub] 异常，重试1次 id=25816 roomid=11 game_id=822 =b"\x1b[31mError 3040007: Invalid Reference Block\x1b[0m\n\x1b[32mEnsure that the reference block exist in the blockchain!\x1b[0m\n\x1b[33mError Details:\nTransaction's reference block did not match. Is this transaction from a different fork?\x1b[0m\n"
2018-12-07 08:05:15,946 reveal_service.py[line:128] ERROR [async_call_sub] 异常，重试2次 id=25816 roomid=11 game_id=822 =b'\x1b[31mError 3040005: Expired Transaction\x1b[0m\n\x1b[32mPlease increase the expiration time of your transaction!\x1b[0m\n\x1b[33mError Details:\nexpired transaction 9ffe9216b13543cd3510081e30451a925ccc6d41cc0699610a867d272f529eb4\x1b[0m\n'
2018-12-07 08:05:16,951 reveal_service.py[line:128] ERROR [async_call_sub] 异常，重试1次 id=25819 roomid=1 game_id=2419 =b'\x1b[31mError 3040005: Expired Transaction\x1b[0m\n\x1b[32mPlease increase the expiration time of your transaction!\x1b[0m\n\x1b[33mError Details:\nexpired transaction 8298ea0b2637a0e3926447560338521f56e8a4ba26fd697b15b620d9821eba37\x1b[0m\n'
2018-12-07 08:05:17,164 reveal_service.py[line:128] ERROR [async_call_sub] 异常，重试1次 id=25817 roomid=12 game_id=344 =b'\x1b[31mError 3040005: Expired Transaction\x1b[0m\n\x1b[32mPlease increase the expiration time of your transaction!\x1b[0m\n\x1b[33mError Details:\nexpired transaction 49a9974e8c257aeeee645ec5f1b63e2a9cb75a91928a4da80e79ce5beb981da9\x1b[0m\n'
2018-12-07 08:05:18,536 reveal_service.py[line:128] ERROR [async_call_sub] 异常，重试3次 id=25816 roomid=11 game_id=822 =b'\x1b[31mError 3040005: Expired Transaction\x1b[0m\n\x1b[32mPlease increase the expiration time of your transaction!\x1b[0m\n\x1b[33mError Details:\nexpired transaction 9ffe9216b13543cd3510081e30451a925ccc6d41cc0699610a867d272f529eb4\x1b[0m\n'
2018-12-07 08:05:19,060 reveal_service.py[line:128] ERROR [async_call_sub] 异常，重试2次 id=25819 roomid=1 game_id=2419 =b"\x1b[31mError 3040007: Invalid Reference Block\x1b[0m\n\x1b[32mEnsure that the reference block exist in the blockchain!\x1b[0m\n\x1b[33mError Details:\nTransaction's reference block did not match. Is this transaction from a different fork?\x1b[0m\n"
2018-12-07 08:05:19,752 reveal_service.py[line:128] ERROR [async_call_sub] 异常，重试2次 id=25817 roomid=12 game_id=344 =b"\x1b[31mError 3040007: Invalid Reference Block\x1b[0m\n\x1b[32mEnsure that the reference block exist in the blockchain!\x1b[0m\n\x1b[33mError Details:\nTransaction's reference block did not match. Is this transaction from a different fork?\x1b[0m\n"
2018-12-07 08:05:21,854 reveal_service.py[line:128] ERROR [async_call_sub] 异常，重试3次 id=25817 roomid=12 game_id=344 =b'\x1b[31mError 3040005: Expired Transaction\x1b[0m\n\x1b[32mPlease increase the expiration time of your transaction!\x1b[0m\n\x1b[33mError Details:\nexpired transaction 49a9974e8c257aeeee645ec5f1b63e2a9cb75a91928a4da80e79ce5beb981da9\x1b[0m\n'
2018-12-07 08:05:26,749 reveal_service.py[line:128] ERROR [async_call_sub] 异常，重试3次 id=25814 roomid=16 game_id=156 =b'error 2018-12-07T08:05:26.748 thread-0  main.cpp:3151                 main                 ] Failed with error: Parse Error (4)\nUnexpected char \'60\' in ""\n\n\n'
2018-12-07 08:06:05,748 reveal_service.py[line:128] ERROR [async_call_sub] 异常，重试1次 id=25820 roomid=6 game_id=2321 =b'\x1b[31mError 3040005: Expired Transaction\x1b[0m\n\x1b[32mPlease increase the expiration time of your transaction!\x1b[0m\n\x1b[33mError Details:\nexpired transaction f215051aeba07eefb7290acdfa717c59fcb43ab97ca3d98236ef818454e9e903\x1b[0m\n'
2018-12-07 08:06:07,830 reveal_service.py[line:128] ERROR [async_call_sub] 异常，重试2次 id=25820 roomid=6 game_id=2321 =b'\x1b[31mError 3040005: Expired Transaction\x1b[0m\n\x1b[32mPlease increase the expiration time of your transaction!\x1b[0m\n\x1b[33mError Details:\nexpired transaction f215051aeba07eefb7290acdfa717c59fcb43ab97ca3d98236ef818454e9e903\x1b[0m\n'
2018-12-07 08:06:11,315 reveal_service.py[line:128] ERROR [async_call_sub] 异常，重试1次 id=25817 roomid=12 game_id=344 =b'\x1b[31mError 3040005: Expired Transaction\x1b[0m\n\x1b[32mPlease increase the expiration time of your transaction!\x1b[0m\n\x1b[33mError Details:\nexpired transaction 49a9974e8c257aeeee645ec5f1b63e2a9cb75a91928a4da80e79ce5beb981da9\x1b[0m\n'
2018-12-07 08:06:11,969 reveal_service.py[line:128] ERROR [async_call_sub] 异常，重试1次 id=25816 roomid=11 game_id=822 =b'\x1b[31mError 3040005: Expired Transaction\x1b[0m\n\x1b[32mPlease increase the expiration time of your transaction!\x1b[0m\n\x1b[33mError Details:\nexpired transaction 9ffe9216b13543cd3510081e30451a925ccc6d41cc0699610a867d272f529eb4\x1b[0m\n'
2018-12-07 08:06:13,737 reveal_service.py[line:128] ERROR [async_call_sub] 异常，重试2次 id=25816 roomid=11 game_id=822 =b'\x1b[31mError 3040005: Expired Transaction\x1b[0m\n\x1b[32mPlease increase the expiration time of your transaction!\x1b[0m\n\x1b[33mError Details:\nexpired transaction 9ffe9216b13543cd3510081e30451a925ccc6d41cc0699610a867d272f529eb4\x1b[0m\n'
2018-12-07 08:07:06,054 reveal_service.py[line:128] ERROR [async_call_sub] 异常，重试1次 id=25829 roomid=12 game_id=345 =b'\x1b[31mError 3040005: Expired Transaction\x1b[0m\n\x1b[32mPlease increase the expiration time of your transaction!\x1b[0m\n\x1b[33mError Details:\nexpired transaction 97137455a859c709014eb203115f8596a31210317deafe5ce29f79f1863ee41a\x1b[0m\n'
2018-12-07 08:07:06,592 reveal_service.py[line:128] ERROR [async_call_sub] 异常，重试1次 id=25828 roomid=1 game_id=2421 =b"\x1b[31mError 3040007: Invalid Reference Block\x1b[0m\n\x1b[32mEnsure that the reference block exist in the blockchain!\x1b[0m\n\x1b[33mError Details:\nTransaction's reference block did not match. Is this transaction from a different fork?\x1b[0m\n"
2018-12-07 08:07:50,657 reveal_service.py[line:128] ERROR [async_call_sub] 异常，重试1次 id=25831 roomid=8 game_id=1794 =b'\x1b[31mError 3040005: Expired Transaction\x1b[0m\n\x1b[32mPlease increase the expiration time of your transaction!\x1b[0m\n\x1b[33mError Details:\nexpired transaction 413a3b2f08df4c8663daea706e3e267e5ce76535dda779154a4b12161d1429e7\x1b[0m\n'
2018-12-07 08:07:55,485 reveal_service.py[line:128] ERROR [async_call_sub] 异常，重试1次 id=25832 roomid=6 game_id=2323 =b'\x1b[31mError 3040005: Expired Transaction\x1b[0m\n\x1b[32mPlease increase the expiration time of your transaction!\x1b[0m\n\x1b[33mError Details:\nexpired transaction 59787040d8d08e99f61ef81d4af95f330bb6c27f2c38c66b8acdf191b8ce1512\x1b[0m\n'
2018-12-07 08:07:56,912 reveal_service.py[line:128] ERROR [async_call_sub] 异常，重试1次 id=25833 roomid=18 game_id=159 =b'\x1b[31mError 3040005: Expired Transaction\x1b[0m\n\x1b[32mPlease increase the expiration time of your transaction!\x1b[0m\n\x1b[33mError Details:\nexpired transaction 5e0fa98c565e2fc2d29ed9c4ba6369232e7cfd0317bda7d2d689d4792dd06138\x1b[0m\n'
2018-12-07 08:07:57,628 reveal_service.py[line:128] ERROR [async_call_sub] 异常，重试1次 id=25834 roomid=16 game_id=158 =b'\x1b[31mError 3040005: Expired Transaction\x1b[0m\n\x1b[32mPlease increase the expiration time of your transaction!\x1b[0m\n\x1b[33mError Details:\nexpired transaction 4838a5497bc358dd8f3b8e930dc68bc71d6321cbd3de357f49cc3fc83059303a\x1b[0m\n'
2018-12-07 08:07:58,537 reveal_service.py[line:128] ERROR [async_call_sub] 异常，重试2次 id=25833 roomid=18 game_id=159 =b'\x1b[31mError 3040005: Expired Transaction\x1b[0m\n\x1b[32mPlease increase the expiration time of your transaction!\x1b[0m\n\x1b[33mError Details:\nexpired transaction 5e0fa98c565e2fc2d29ed9c4ba6369232e7cfd0317bda7d2d689d4792dd06138\x1b[0m\n'
2018-12-07 08:08:00,857 reveal_service.py[line:128] ERROR [async_call_sub] 异常，重试1次 id=25835 roomid=11 game_id=824 =b"\x1b[31mError 3040007: Invalid Reference Block\x1b[0m\n\x1b[32mEnsure that the reference block exist in the blockchain!\x1b[0m\n\x1b[33mError Details:\nTransaction's reference block did not match. Is this transaction from a different fork?\x1b[0m\n"
2018-12-07 08:08:01,169 reveal_service.py[line:128] ERROR [async_call_sub] 异常，重试1次 id=25836 roomid=12 game_id=346 =b'\x1b[31mError 3040005: Expired Transaction\x1b[0m\n\x1b[32mPlease increase the expiration time of your transaction!\x1b[0m\n\x1b[33mError Details:\nexpired transaction ac91b866dc6c6251a86f257dbad9c5cff2a031529208014f38d759e0e7f43990\x1b[0m\n'
2018-12-07 08:08:27,737 reveal_service.py[line:128] ERROR [async_call_sub] 异常，重试2次 id=25832 roomid=6 game_id=2323 =b'error 2018-12-07T08:08:27.736 thread-0  main.cpp:3151                 main                 ] Failed with error: Parse Error (4)\nUnexpected char \'60\' in ""\n\n\n'
2018-12-07 08:08:29,830 reveal_service.py[line:128] ERROR [async_call_sub] 异常，重试3次 id=25832 roomid=6 game_id=2323 =b'\x1b[31mError 3040005: Expired Transaction\x1b[0m\n\x1b[32mPlease increase the expiration time of your transaction!\x1b[0m\n\x1b[33mError Details:\nexpired transaction 59787040d8d08e99f61ef81d4af95f330bb6c27f2c38c66b8acdf191b8ce1512\x1b[0m\n'
2018-12-07 08:08:53,394 reveal_service.py[line:128] ERROR [async_call_sub] 异常，重试1次 id=25839 roomid=16 game_id=159 =b"\x1b[31mError 3040007: Invalid Reference Block\x1b[0m\n\x1b[32mEnsure that the reference block exist in the blockchain!\x1b[0m\n\x1b[33mError Details:\nTransaction's reference block did not match. Is this transaction from a different fork?\x1b[0m\n"
2018-12-07 08:08:53,796 reveal_service.py[line:128] ERROR [async_call_sub] 异常，重试1次 id=25840 roomid=18 game_id=160 =b"\x1b[31mError 3040007: Invalid Reference Block\x1b[0m\n\x1b[32mEnsure that the reference block exist in the blockchain!\x1b[0m\n\x1b[33mError Details:\nTransaction's reference block did not match. Is this transaction from a different fork?\x1b[0m\n"
2018-12-07 08:08:53,962 reveal_service.py[line:128] ERROR [async_call_sub] 异常，重试1次 id=25841 roomid=1 game_id=2423 =b'\x1b[31mError 3040005: Expired Transaction\x1b[0m\n\x1b[32mPlease increase the expiration time of your transaction!\x1b[0m\n\x1b[33mError Details:\nexpired transaction 4f27291eda603490b7effea6399caa7af3725709449933d112f13dabdc302999\x1b[0m\n'
2018-12-07 08:08:55,065 reveal_service.py[line:128] ERROR [async_call_sub] 异常，重试2次 id=25839 roomid=16 game_id=159 =b"\x1b[31mError 3040007: Invalid Reference Block\x1b[0m\n\x1b[32mEnsure that the reference block exist in the blockchain!\x1b[0m\n\x1b[33mError Details:\nTransaction's reference block did not match. Is this transaction from a different fork?\x1b[0m\n"
2018-12-07 08:08:55,407 reveal_service.py[line:128] ERROR [async_call_sub] 异常，重试2次 id=25840 roomid=18 game_id=160 =b'\x1b[31mError 3040005: Expired Transaction\x1b[0m\n\x1b[32mPlease increase the expiration time of your transaction!\x1b[0m\n\x1b[33mError Details:\nexpired transaction c45a8b91e9daddaf7b4f4f84064d739e43214e5f774c3d17f999d86c1d4327f6\x1b[0m\n'
2018-12-07 08:08:55,559 reveal_service.py[line:128] ERROR [async_call_sub] 异常，重试2次 id=25841 roomid=1 game_id=2423 =b'\x1b[31mError 3040005: Expired Transaction\x1b[0m\n\x1b[32mPlease increase the expiration time of your transaction!\x1b[0m\n\x1b[33mError Details:\nexpired transaction 4f27291eda603490b7effea6399caa7af3725709449933d112f13dabdc302999\x1b[0m\n'
2018-12-07 08:08:55,893 reveal_service.py[line:128] ERROR [async_call_sub] 异常，重试1次 id=25842 roomid=12 game_id=347 =b"\x1b[31mError 3040007: Invalid Reference Block\x1b[0m\n\x1b[32mEnsure that the reference block exist in the blockchain!\x1b[0m\n\x1b[33mError Details:\nTransaction's reference block did not match. Is this transaction from a different fork?\x1b[0m\n"
2018-12-07 08:08:57,227 reveal_service.py[line:128] ERROR [async_call_sub] 异常，重试3次 id=25841 roomid=1 game_id=2423 =b'\x1b[31mError 3040005: Expired Transaction\x1b[0m\n\x1b[32mPlease increase the expiration time of your transaction!\x1b[0m\n\x1b[33mError Details:\nexpired transaction 4f27291eda603490b7effea6399caa7af3725709449933d112f13dabdc302999\x1b[0m\n'
2018-12-07 08:09:26,341 reveal_service.py[line:128] ERROR [async_call_sub] 异常，重试1次 id=25843 roomid=11 game_id=825 =b'error 2018-12-07T08:09:26.339 thread-0  main.cpp:3151                 main                 ] Failed with error: Parse Error (4)\nUnexpected char \'60\' in ""\n\n\n'
2018-12-07 08:09:27,163 reveal_service.py[line:128] ERROR [async_call_sub] 异常，重试3次 id=25840 roomid=18 game_id=160 =b'error 2018-12-07T08:09:27.160 thread-0  main.cpp:3151                 main                 ] Failed with error: Parse Error (4)\nUnexpected char \'60\' in ""\n\n\n'
2018-12-07 08:09:56,087 reveal_service.py[line:128] ERROR [async_call_sub] 异常，重试1次 id=25841 roomid=1 game_id=2423 =b'error 2018-12-07T08:09:56.085 thread-0  main.cpp:3151                 main                 ] Failed with error: Parse Error (4)\nUnexpected char \'60\' in ""\n\n\n'
2018-12-07 08:10:07,697 reveal_service.py[line:128] ERROR [async_call_sub] 异常，重试1次 id=25844 roomid=8 game_id=1796 =b'error 2018-12-07T08:10:07.694 thread-0  main.cpp:3151                 main                 ] Failed with error: Parse Error (4)\nUnexpected char \'60\' in ""\n\n\n'
2018-12-07 08:10:10,388 reveal_service.py[line:128] ERROR [async_call_sub] 异常，重试1次 id=25840 roomid=18 game_id=160 =b'error 2018-12-07T08:10:10.386 thread-0  main.cpp:3151                 main                 ] Failed with error: Parse Error (4)\nUnexpected char \'60\' in ""\n\n\n'
2018-12-07 08:10:19,708 reveal_service.py[line:128] ERROR [async_call_sub] 异常，重试1次 id=25847 roomid=6 game_id=2324 =b'error 2018-12-07T08:10:19.707 thread-0  main.cpp:3151                 main                 ] Failed with error: Parse Error (4)\nUnexpected char \'60\' in ""\n\n\n'
2018-12-07 08:10:39,516 reveal_service.py[line:128] ERROR [async_call_sub] 异常，重试2次 id=25844 roomid=8 game_id=1796 =b'error 2018-12-07T08:10:39.514 thread-0  main.cpp:3151                 main                 ] Failed with error: Parse Error (4)\nUnexpected char \'60\' in ""\n\n\n'
2018-12-07 08:10:43,130 reveal_service.py[line:128] ERROR [async_call_sub] 异常，重试2次 id=25840 roomid=18 game_id=160 =b'error 2018-12-07T08:10:43.129 thread-0  main.cpp:3151                 main                 ] Failed with error: Parse Error (4)\nUnexpected char \'60\' in ""\n\n\n'
2018-12-07 08:11:10,943 reveal_service.py[line:128] ERROR [async_call_sub] 异常，重试3次 id=25844 roomid=8 game_id=1796 =b'error 2018-12-07T08:11:10.941 thread-0  main.cpp:3151                 main                 ] Failed with error: Parse Error (4)\nUnexpected char \'60\' in ""\n\n\n'
2018-12-07 08:13:09,577 reveal_service.py[line:128] ERROR [async_call_sub] 异常，重试1次 id=25866 roomid=8 game_id=1797 =b'\x1b[31mError 3050003: eosio_assert_message assertion failure\x1b[0m\n\x1b[33mError Details:\nassertion failure with message: 100013 invalid room status\npending console output: \x1b[0m\n'
2018-12-07 08:27:06,943 seed_service.py[line:125] ERROR no seed data
2018-12-07 08:27:06,943 seed_service.py[line:44] ERROR get_seed 异常 =no seed data
2018-12-07 08:27:06,943 views.py[line:78] ERROR api get_seed 异常=no seed data
2018-12-07 08:41:42,286 seed_service.py[line:125] ERROR no seed data
2018-12-07 08:41:42,286 seed_service.py[line:44] ERROR get_seed 异常 =no seed data
2018-12-07 08:41:42,286 views.py[line:78] ERROR api get_seed 异常=no seed data
2018-12-07 09:33:36,310 reveal_service.py[line:128] ERROR [async_call_sub] 异常，重试1次 id=26528 roomid=6 game_id=2415 =b'\x1b[31mError 3050003: eosio_assert_message assertion failure\x1b[0m\n\x1b[33mError Details:\nassertion failure with message: 100013 invalid room status\npending console output: \x1b[0m\n'
2018-12-07 11:24:16,624 reveal_service.py[line:144] ERROR 〓REVEAL〓 房间新建后第一次开奖，且无人下注 开奖失败 roomid=20 b'\x1b[31mError 3050003: eosio_assert_message assertion failure\x1b[0m\n\x1b[33mError Details:\nassertion failure with message: 100016 room not found\npending console output: \x1b[0m\n'
2018-12-07 11:24:16,703 reveal_service.py[line:144] ERROR 〓REVEAL〓 房间新建后第一次开奖，且无人下注 开奖失败 roomid=20 b'\x1b[31mError 3050003: eosio_assert_message assertion failure\x1b[0m\n\x1b[33mError Details:\nassertion failure with message: 100016 room not found\npending console output: \x1b[0m\n'
2018-12-07 11:24:16,720 reveal_service.py[line:144] ERROR 〓REVEAL〓 房间新建后第一次开奖，且无人下注 开奖失败 roomid=20 b'\x1b[31mError 3050003: eosio_assert_message assertion failure\x1b[0m\n\x1b[33mError Details:\nassertion failure with message: 100016 room not found\npending console output: \x1b[0m\n'
2018-12-07 11:24:16,925 reveal_service.py[line:144] ERROR 〓REVEAL〓 房间新建后第一次开奖，且无人下注 开奖失败 roomid=20 b'\x1b[31mError 3050003: eosio_assert_message assertion failure\x1b[0m\n\x1b[33mError Details:\nassertion failure with message: 100016 room not found\npending console output: \x1b[0m\n'
2018-12-07 11:24:17,031 reveal_service.py[line:144] ERROR 〓REVEAL〓 房间新建后第一次开奖，且无人下注 开奖失败 roomid=20 b'\x1b[31mError 3050003: eosio_assert_message assertion failure\x1b[0m\n\x1b[33mError Details:\nassertion failure with message: 100016 room not found\npending console output: \x1b[0m\n'
2018-12-07 11:24:17,151 reveal_service.py[line:144] ERROR 〓REVEAL〓 房间新建后第一次开奖，且无人下注 开奖失败 roomid=20 b'\x1b[31mError 3050003: eosio_assert_message assertion failure\x1b[0m\n\x1b[33mError Details:\nassertion failure with message: 100016 room not found\npending console output: \x1b[0m\n'
2018-12-07 11:24:17,531 reveal_service.py[line:144] ERROR 〓REVEAL〓 房间新建后第一次开奖，且无人下注 开奖失败 roomid=20 b'\x1b[31mError 3050003: eosio_assert_message assertion failure\x1b[0m\n\x1b[33mError Details:\nassertion failure with message: 100016 room not found\npending console output: \x1b[0m\n'
2018-12-07 11:24:17,609 reveal_service.py[line:144] ERROR 〓REVEAL〓 房间新建后第一次开奖，且无人下注 开奖失败 roomid=20 b'\x1b[31mError 3050003: eosio_assert_message assertion failure\x1b[0m\n\x1b[33mError Details:\nassertion failure with message: 100016 room not found\npending console output: \x1b[0m\n'
2018-12-07 11:24:17,809 reveal_service.py[line:144] ERROR 〓REVEAL〓 房间新建后第一次开奖，且无人下注 开奖失败 roomid=20 (pymysql.err.IntegrityError) (1062, "Duplicate entry '20-2' for key 'uix_id_name'") [SQL: 'INSERT INTO room_seed (room_id, game_id, house_seed_hash, house_seed, expire_timestamp, signature, status, fail_count, created_at, environment) VALUES (%(room_id)s, %(game_id)s, %(house_seed_hash)s, %(house_seed)s, %(expire_timestamp)s, %(signature)s, %(status)s, %(fail_count)s, %(created_at)s, %(environment)s)'] [parameters: {'room_id': 20, 'game_id': 2, 'house_seed_hash': '34cb981800c75348e8faefd4e59d91a293115a96dcfea6c4982e85d558cff4c6', 'house_seed': '504d3d567908302b1411f588f1cc50dd39cc343edde233b83746f965125ab08b', 'expire_timestamp': 1544181977, 'signature': 'SIG_K1_KhC1MLn2q4TBDoL5EaRpGSx5AN8aVnWYeXqW2yuvWFk9aY1P8N1knvnzu37KCV2ziDKTsfik1f4Pm4x93AfNdccAbMYWS2', 'status': 1, 'fail_count': 0, 'created_at': 1544181857.803317, 'environment': 'PRO'}] (Background on this error at: http://sqlalche.me/e/gkpj)
2018-12-07 12:00:06,008 reveal_service.py[line:128] ERROR [async_call_sub] 异常，重试1次 id=27700 roomid=8 game_id=2055 =b'\x1b[31mError 3050003: eosio_assert_message assertion failure\x1b[0m\n\x1b[33mError Details:\nassertion failure with message: 100013 invalid room status\npending console output: \x1b[0m\n'
2018-12-07 12:00:13,440 reveal_service.py[line:128] ERROR [async_call_sub] 异常，重试1次 id=27702 roomid=11 game_id=1084 =b'\x1b[31mError 3050003: eosio_assert_message assertion failure\x1b[0m\n\x1b[33mError Details:\nassertion failure with message: 100013 invalid room status\npending console output: \x1b[0m\n'
2018-12-07 12:00:15,653 seed_service.py[line:125] ERROR no seed data
2018-12-07 12:00:15,653 seed_service.py[line:44] ERROR get_seed 异常 =no seed data
2018-12-07 12:00:15,653 views.py[line:78] ERROR api get_seed 异常=no seed data
2018-12-07 12:00:46,804 reveal_service.py[line:128] ERROR [async_call_sub] 异常，重试1次 id=27704 roomid=1 game_id=2685 =b'\x1b[31mError 3050003: eosio_assert_message assertion failure\x1b[0m\n\x1b[33mError Details:\nassertion failure with message: 100013 invalid room status\npending console output: \x1b[0m\n'
2018-12-07 12:00:47,349 reveal_service.py[line:128] ERROR [async_call_sub] 异常，重试1次 id=27705 roomid=12 game_id=610 =b'\x1b[31mError 3040005: Expired Transaction\x1b[0m\n\x1b[32mPlease increase the expiration time of your transaction!\x1b[0m\n\x1b[33mError Details:\nexpired transaction 829aecc923f733bc39eda142ca45040530a1ce53a9711c2d4bdae7ddc4e32957\x1b[0m\n'
2018-12-07 12:00:49,552 reveal_service.py[line:128] ERROR [async_call_sub] 异常，重试2次 id=27704 roomid=1 game_id=2685 =b'\x1b[31mError 3040005: Expired Transaction\x1b[0m\n\x1b[32mPlease increase the expiration time of your transaction!\x1b[0m\n\x1b[33mError Details:\nexpired transaction 9de439b5e227b9fe238c23185f87ae5cc1ad68fea85c78433ed170e2f4fee3eb\x1b[0m\n'
2018-12-07 12:00:51,870 reveal_service.py[line:128] ERROR [async_call_sub] 异常，重试3次 id=27704 roomid=1 game_id=2685 =b'\x1b[31mError 3050003: eosio_assert_message assertion failure\x1b[0m\n\x1b[33mError Details:\nassertion failure with message: 100013 invalid room status\npending console output: \x1b[0m\n'
2018-12-07 12:00:52,476 reveal_service.py[line:128] ERROR [async_call_sub] 异常，重试1次 id=27706 roomid=6 game_id=2583 =b'\x1b[31mError 3040005: Expired Transaction\x1b[0m\n\x1b[32mPlease increase the expiration time of your transaction!\x1b[0m\n\x1b[33mError Details:\nexpired transaction 2e994a619a093e8d25078d4ed2cb0f5b9af25125598647da1f13df0dbf3a7f10\x1b[0m\n'
2018-12-07 12:00:58,193 reveal_service.py[line:128] ERROR [async_call_sub] 异常，重试1次 id=27707 roomid=18 game_id=422 =b'\x1b[31mError 3040005: Expired Transaction\x1b[0m\n\x1b[32mPlease increase the expiration time of your transaction!\x1b[0m\n\x1b[33mError Details:\nexpired transaction 832c60658a5dd188670cb288abef3695c792a9b34e636d4ef1e10fa22506f55e\x1b[0m\n'
2018-12-07 12:01:08,565 reveal_service.py[line:128] ERROR [async_call_sub] 异常，重试1次 id=27709 roomid=11 game_id=1085 =b'\x1b[31mError 3040005: Expired Transaction\x1b[0m\n\x1b[32mPlease increase the expiration time of your transaction!\x1b[0m\n\x1b[33mError Details:\nexpired transaction 9d544032a0a760b0aebb63a89ba9ec17138e33c4f5a0904de973b47a41e8002f\x1b[0m\n'
2018-12-07 12:01:14,830 reveal_service.py[line:128] ERROR [async_call_sub] 异常，重试1次 id=27710 roomid=16 game_id=423 =b'\x1b[31mError 3050003: eosio_assert_message assertion failure\x1b[0m\n\x1b[33mError Details:\nassertion failure with message: 100013 invalid room status\npending console output: \x1b[0m\n'
2018-12-07 12:01:17,172 reveal_service.py[line:128] ERROR [async_call_sub] 异常，重试2次 id=27710 roomid=16 game_id=423 =b'\x1b[31mError 3050003: eosio_assert_message assertion failure\x1b[0m\n\x1b[33mError Details:\nassertion failure with message: 100013 invalid room status\npending console output: \x1b[0m\n'
2018-12-07 12:01:19,169 reveal_service.py[line:128] ERROR [async_call_sub] 异常，重试3次 id=27710 roomid=16 game_id=423 =b'\x1b[31mError 3050003: eosio_assert_message assertion failure\x1b[0m\n\x1b[33mError Details:\nassertion failure with message: 100013 invalid room status\npending console output: \x1b[0m\n'
2018-12-07 12:02:39,156 reveal_service.py[line:128] ERROR [async_call_sub] 异常，重试1次 id=27717 roomid=6 game_id=2585 =b'\x1b[31mError 3040005: Expired Transaction\x1b[0m\n\x1b[32mPlease increase the expiration time of your transaction!\x1b[0m\n\x1b[33mError Details:\nexpired transaction 76fbb3a6be7be80ba06503f40f4da29fc52b9913d1fa9be42b7bef5d04568bec\x1b[0m\n'
2018-12-07 12:02:44,878 reveal_service.py[line:128] ERROR [async_call_sub] 异常，重试1次 id=27718 roomid=18 game_id=424 =b'\x1b[31mError 3040005: Expired Transaction\x1b[0m\n\x1b[32mPlease increase the expiration time of your transaction!\x1b[0m\n\x1b[33mError Details:\nexpired transaction 1ed2da301b5b308fc5cb4d94eecfe773d992839e87fc6bd9835f1a86279a585b\x1b[0m\n'
2018-12-07 12:02:55,001 reveal_service.py[line:128] ERROR [async_call_sub] 异常，重试1次 id=27720 roomid=11 game_id=1087 =b"\x1b[31mError 3040007: Invalid Reference Block\x1b[0m\n\x1b[32mEnsure that the reference block exist in the blockchain!\x1b[0m\n\x1b[33mError Details:\nTransaction's reference block did not match. Is this transaction from a different fork?\x1b[0m\n"
2018-12-07 12:04:19,041 reveal_service.py[line:128] ERROR [async_call_sub] 异常，重试1次 id=27726 roomid=12 game_id=614 =b"\x1b[31mError 3040007: Invalid Reference Block\x1b[0m\n\x1b[32mEnsure that the reference block exist in the blockchain!\x1b[0m\n\x1b[33mError Details:\nTransaction's reference block did not match. Is this transaction from a different fork?\x1b[0m\n"
2018-12-07 12:04:25,845 reveal_service.py[line:128] ERROR [async_call_sub] 异常，重试1次 id=27727 roomid=6 game_id=2587 =b'\x1b[31mError 3040005: Expired Transaction\x1b[0m\n\x1b[32mPlease increase the expiration time of your transaction!\x1b[0m\n\x1b[33mError Details:\nexpired transaction afc1a50e143f468cbd33bf68f14d89eedb43d698ef00afe9b042a4056acc6420\x1b[0m\n'
2018-12-07 12:04:31,119 reveal_service.py[line:128] ERROR [async_call_sub] 异常，重试1次 id=27729 roomid=18 game_id=426 =b"\x1b[31mError 3040007: Invalid Reference Block\x1b[0m\n\x1b[32mEnsure that the reference block exist in the blockchain!\x1b[0m\n\x1b[33mError Details:\nTransaction's reference block did not match. Is this transaction from a different fork?\x1b[0m\n"
2018-12-07 12:04:41,599 reveal_service.py[line:128] ERROR [async_call_sub] 异常，重试1次 id=27730 roomid=11 game_id=1089 =b'\x1b[31mError 3040005: Expired Transaction\x1b[0m\n\x1b[32mPlease increase the expiration time of your transaction!\x1b[0m\n\x1b[33mError Details:\nexpired transaction 8de99b87b896f041cb816bace4b7cf9c4e012370aff72594147355a187e9ea15\x1b[0m\n'
2018-12-07 12:05:13,379 reveal_service.py[line:128] ERROR [async_call_sub] 异常，重试2次 id=27730 roomid=11 game_id=1089 =b'error 2018-12-07T12:05:13.378 thread-0  main.cpp:3151                 main                 ] Failed with error: Parse Error (4)\nUnexpected char \'60\' in ""\n\n\n'
2018-12-07 12:05:19,583 reveal_service.py[line:128] ERROR [async_call_sub] 异常，重试1次 id=27732 roomid=6 game_id=2588 =b"\x1b[31mError 3040007: Invalid Reference Block\x1b[0m\n\x1b[32mEnsure that the reference block exist in the blockchain!\x1b[0m\n\x1b[33mError Details:\nTransaction's reference block did not match. Is this transaction from a different fork?\x1b[0m\n"
2018-12-07 12:05:44,254 reveal_service.py[line:128] ERROR [async_call_sub] 异常，重试1次 id=27731 roomid=12 game_id=615 =b'error 2018-12-07T12:05:44.252 thread-0  main.cpp:3151                 main                 ] Failed with error: Parse Error (4)\nUnexpected char \'60\' in ""\n\n\n'
2018-12-07 12:06:07,562 reveal_service.py[line:128] ERROR [async_call_sub] 异常，重试1次 id=27735 roomid=11 game_id=1090 =b"\x1b[31mError 3040007: Invalid Reference Block\x1b[0m\n\x1b[32mEnsure that the reference block exist in the blockchain!\x1b[0m\n\x1b[33mError Details:\nTransaction's reference block did not match. Is this transaction from a different fork?\x1b[0m\n"
2018-12-07 12:06:09,558 reveal_service.py[line:128] ERROR [async_call_sub] 异常，重试2次 id=27735 roomid=11 game_id=1090 =b"\x1b[31mError 3040007: Invalid Reference Block\x1b[0m\n\x1b[32mEnsure that the reference block exist in the blockchain!\x1b[0m\n\x1b[33mError Details:\nTransaction's reference block did not match. Is this transaction from a different fork?\x1b[0m\n"
2018-12-07 12:06:13,491 reveal_service.py[line:128] ERROR [async_call_sub] 异常，重试1次 id=27737 roomid=6 game_id=2589 =b'\x1b[31mError 3040005: Expired Transaction\x1b[0m\n\x1b[32mPlease increase the expiration time of your transaction!\x1b[0m\n\x1b[33mError Details:\nexpired transaction 6eb16263cb9fa7344e3dcdb8de79a3438c0eed2e0ae4a90b4c8b95ded470ea1d\x1b[0m\n'
2018-12-07 12:06:15,832 reveal_service.py[line:128] ERROR [async_call_sub] 异常，重试2次 id=27737 roomid=6 game_id=2589 =b'\x1b[31mError 3040005: Expired Transaction\x1b[0m\n\x1b[32mPlease increase the expiration time of your transaction!\x1b[0m\n\x1b[33mError Details:\nexpired transaction 6eb16263cb9fa7344e3dcdb8de79a3438c0eed2e0ae4a90b4c8b95ded470ea1d\x1b[0m\n'
2018-12-07 12:07:03,134 reveal_service.py[line:128] ERROR [async_call_sub] 异常，重试1次 id=27740 roomid=11 game_id=1091 =b'\x1b[31mError 3040005: Expired Transaction\x1b[0m\n\x1b[32mPlease increase the expiration time of your transaction!\x1b[0m\n\x1b[33mError Details:\nexpired transaction 4610c6239051f6128e493b138dbd5cba288fb590efd22ed74b5a5f560fd8f4c6\x1b[0m\n'
2018-12-07 12:07:06,053 reveal_service.py[line:128] ERROR [async_call_sub] 异常，重试1次 id=27741 roomid=8 game_id=2063 =b'\x1b[31mError 3040005: Expired Transaction\x1b[0m\n\x1b[32mPlease increase the expiration time of your transaction!\x1b[0m\n\x1b[33mError Details:\nexpired transaction 96ee1e78f10ef273ac16ca3fb25bd692a1a439376d06e5a2483ffaf5967e9cf1\x1b[0m\n'
2018-12-07 12:07:08,032 reveal_service.py[line:128] ERROR [async_call_sub] 异常，重试2次 id=27741 roomid=8 game_id=2063 =b"\x1b[31mError 3040007: Invalid Reference Block\x1b[0m\n\x1b[32mEnsure that the reference block exist in the blockchain!\x1b[0m\n\x1b[33mError Details:\nTransaction's reference block did not match. Is this transaction from a different fork?\x1b[0m\n"
2018-12-07 12:07:10,826 reveal_service.py[line:128] ERROR [async_call_sub] 异常，重试1次 id=27742 roomid=18 game_id=429 =b"\x1b[31mError 3040007: Invalid Reference Block\x1b[0m\n\x1b[32mEnsure that the reference block exist in the blockchain!\x1b[0m\n\x1b[33mError Details:\nTransaction's reference block did not match. Is this transaction from a different fork?\x1b[0m\n"
2018-12-07 12:07:12,807 reveal_service.py[line:128] ERROR [async_call_sub] 异常，重试2次 id=27742 roomid=18 game_id=429 =b"\x1b[31mError 3040007: Invalid Reference Block\x1b[0m\n\x1b[32mEnsure that the reference block exist in the blockchain!\x1b[0m\n\x1b[33mError Details:\nTransaction's reference block did not match. Is this transaction from a different fork?\x1b[0m\n"
2018-12-07 12:07:14,812 reveal_service.py[line:128] ERROR [async_call_sub] 异常，重试3次 id=27742 roomid=18 game_id=429 =b'\x1b[31mError 3040005: Expired Transaction\x1b[0m\n\x1b[32mPlease increase the expiration time of your transaction!\x1b[0m\n\x1b[33mError Details:\nexpired transaction 9ff03235ab6fcb8c62e655a9c7b6599dabcc000e40f081b5b2f12e74d5780fb2\x1b[0m\n'
2018-12-07 12:07:30,344 reveal_service.py[line:128] ERROR [async_call_sub] 异常，重试1次 id=27744 roomid=12 game_id=617 =b"\x1b[31mError 3040007: Invalid Reference Block\x1b[0m\n\x1b[32mEnsure that the reference block exist in the blockchain!\x1b[0m\n\x1b[33mError Details:\nTransaction's reference block did not match. Is this transaction from a different fork?\x1b[0m\n"
2018-12-07 12:07:32,296 reveal_service.py[line:128] ERROR [async_call_sub] 异常，重试2次 id=27744 roomid=12 game_id=617 =b"\x1b[31mError 3040007: Invalid Reference Block\x1b[0m\n\x1b[32mEnsure that the reference block exist in the blockchain!\x1b[0m\n\x1b[33mError Details:\nTransaction's reference block did not match. Is this transaction from a different fork?\x1b[0m\n"
2018-12-07 12:07:57,721 reveal_service.py[line:128] ERROR [async_call_sub] 异常，重试1次 id=27745 roomid=11 game_id=1092 =b"\x1b[31mError 3040007: Invalid Reference Block\x1b[0m\n\x1b[32mEnsure that the reference block exist in the blockchain!\x1b[0m\n\x1b[33mError Details:\nTransaction's reference block did not match. Is this transaction from a different fork?\x1b[0m\n"
2018-12-07 12:08:02,091 reveal_service.py[line:128] ERROR [async_call_sub] 异常，重试1次 id=27746 roomid=8 game_id=2064 =b"\x1b[31mError 3040007: Invalid Reference Block\x1b[0m\n\x1b[32mEnsure that the reference block exist in the blockchain!\x1b[0m\n\x1b[33mError Details:\nTransaction's reference block did not match. Is this transaction from a different fork?\x1b[0m\n"
2018-12-07 12:08:33,987 reveal_service.py[line:128] ERROR [async_call_sub] 异常，重试2次 id=27746 roomid=8 game_id=2064 =b'error 2018-12-07T12:08:33.986 thread-0  main.cpp:3151                 main                 ] Failed with error: Parse Error (4)\nUnexpected char \'60\' in ""\n\n\n'
2018-12-07 12:08:56,225 reveal_service.py[line:128] ERROR [async_call_sub] 异常，重试1次 id=27750 roomid=6 game_id=2592 =b'\x1b[31mError 3040005: Expired Transaction\x1b[0m\n\x1b[32mPlease increase the expiration time of your transaction!\x1b[0m\n\x1b[33mError Details:\nexpired transaction 0bd249ec6b3ee269f02630e462c1829146f66ec7fbc1502df39dd60dd1d0fbe9\x1b[0m\n'
2018-12-07 12:09:50,088 reveal_service.py[line:128] ERROR [async_call_sub] 异常，重试1次 id=27751 roomid=12 game_id=619 =b'error 2018-12-07T12:09:50.087 thread-0  main.cpp:3151                 main                 ] Failed with error: Parse Error (4)\nUnexpected char \'60\' in ""\n\n\n'
2018-12-07 12:10:14,455 reveal_service.py[line:128] ERROR [async_call_sub] 异常，重试1次 id=27753 roomid=11 game_id=1094 =b'error 2018-12-07T12:10:14.454 thread-0  main.cpp:3151                 main                 ] Failed with error: Parse Error (4)\nUnexpected char \'60\' in ""\n\n\n'
2018-12-07 12:10:20,167 reveal_service.py[line:128] ERROR [async_call_sub] 异常，重试1次 id=27754 roomid=6 game_id=2593 =b'error 2018-12-07T12:10:20.165 thread-0  main.cpp:3151                 main                 ] Failed with error: Parse Error (4)\nUnexpected char \'60\' in ""\n\n\n'
2018-12-07 12:10:21,542 reveal_service.py[line:128] ERROR [async_call_sub] 异常，重试2次 id=27751 roomid=12 game_id=619 =b'error 2018-12-07T12:10:21.541 thread-0  main.cpp:3151                 main                 ] Failed with error: Parse Error (4)\nUnexpected char \'60\' in ""\n\n\n'
2018-12-07 12:10:24,614 reveal_service.py[line:128] ERROR [async_call_sub] 异常，重试1次 id=27755 roomid=8 game_id=2066 =b'\x1b[31mError 3040005: Expired Transaction\x1b[0m\n\x1b[32mPlease increase the expiration time of your transaction!\x1b[0m\n\x1b[33mError Details:\nexpired transaction 025088ed5a5ec198996e82f0a7c19833d138185f4ae2ea339f3309013fde92ba\x1b[0m\n'
2018-12-07 12:11:18,041 reveal_service.py[line:128] ERROR [async_call_sub] 异常，重试1次 id=27757 roomid=12 game_id=620 =b'\x1b[31mError 3040005: Expired Transaction\x1b[0m\n\x1b[32mPlease increase the expiration time of your transaction!\x1b[0m\n\x1b[33mError Details:\nexpired transaction 69947f3b96dbeed3c271b134ad5ce4b19d46d943ce5d98b3cf26fec57cbe206f\x1b[0m\n'
2018-12-07 12:16:20,193 connector.py[line:28] ERROR invalid room status roomid=21 gameid=1 异常已被处理
2018-12-07 12:16:20,248 connector.py[line:28] ERROR invalid room status roomid=21 gameid=1 异常已被处理
2018-12-07 12:16:20,500 connector.py[line:28] ERROR invalid room status roomid=21 gameid=1 异常已被处理
2018-12-07 12:16:20,758 connector.py[line:28] ERROR invalid room status roomid=21 gameid=1 异常已被处理
2018-12-07 12:16:21,325 reveal_service.py[line:144] ERROR 〓REVEAL〓 房间新建后第一次开奖，且无人下注 开奖失败 roomid=21 (pymysql.err.IntegrityError) (1062, "Duplicate entry '21-2' for key 'uix_id_name'") [SQL: 'INSERT INTO room_seed (room_id, game_id, house_seed_hash, house_seed, expire_timestamp, signature, status, fail_count, created_at, environment) VALUES (%(room_id)s, %(game_id)s, %(house_seed_hash)s, %(house_seed)s, %(expire_timestamp)s, %(signature)s, %(status)s, %(fail_count)s, %(created_at)s, %(environment)s)'] [parameters: {'room_id': 21, 'game_id': 2, 'house_seed_hash': '5105b00b034bb9980f67fd3f523757fdb0807de791581f3e9d81167f512f9177', 'house_seed': 'c2c0bda98dddc8e73a0ef790567e770007fb817cd74809b5d71c3617f44e1678', 'expire_timestamp': 1544185100, 'signature': 'SIG_K1_JvFXcMXePpYjrG6E2g93mErrS5z3Qb9GaE3U8qdcymoRcwAdazL7bmUcUGZV4bRWQDw7vYsk4Q3tDkMX41fg3Aaxcm9ayn', 'status': 1, 'fail_count': 0, 'created_at': 1544184981.1777072, 'environment': 'PRO'}] (Background on this error at: http://sqlalche.me/e/gkpj)
2018-12-07 12:16:21,375 connector.py[line:28] ERROR invalid room status roomid=21 gameid=1 异常已被处理
2018-12-07 12:16:22,922 reveal_service.py[line:144] ERROR 〓REVEAL〓 房间新建后第一次开奖，且无人下注 开奖失败 roomid=21 (pymysql.err.IntegrityError) (1062, "Duplicate entry '21-2' for key 'uix_id_name'") [SQL: 'INSERT INTO room_seed (room_id, game_id, house_seed_hash, house_seed, expire_timestamp, signature, status, fail_count, created_at, environment) VALUES (%(room_id)s, %(game_id)s, %(house_seed_hash)s, %(house_seed)s, %(expire_timestamp)s, %(signature)s, %(status)s, %(fail_count)s, %(created_at)s, %(environment)s)'] [parameters: {'room_id': 21, 'game_id': 2, 'house_seed_hash': 'fe780d05318c93e8c23e6d19e1196b5ce6c945b5e152ae360dba822404468bc8', 'house_seed': '18b1baf166c5d69fcb8e671112a7235cc39175f6b4a125a58839f4fb7075d116', 'expire_timestamp': 1544185100, 'signature': 'SIG_K1_K5Eks4RL6yiu4P1zmJREbB5rYF3pqSQx5Ug5dfNb33AA3iLCFf2szCe8PsuMxecQGvap5y9ApM6VULqBEV8CLCxszjxBjW', 'status': 1, 'fail_count': 0, 'created_at': 1544184982.764432, 'environment': 'PRO'}] (Background on this error at: http://sqlalche.me/e/gkpj)
2018-12-07 12:16:24,586 reveal_service.py[line:144] ERROR 〓REVEAL〓 房间新建后第一次开奖，且无人下注 开奖失败 roomid=21 (pymysql.err.IntegrityError) (1062, "Duplicate entry '21-2' for key 'uix_id_name'") [SQL: 'INSERT INTO room_seed (room_id, game_id, house_seed_hash, house_seed, expire_timestamp, signature, status, fail_count, created_at, environment) VALUES (%(room_id)s, %(game_id)s, %(house_seed_hash)s, %(house_seed)s, %(expire_timestamp)s, %(signature)s, %(status)s, %(fail_count)s, %(created_at)s, %(environment)s)'] [parameters: {'room_id': 21, 'game_id': 2, 'house_seed_hash': '8680c96947215e8a68ec9772aac271e0019867a426d9087e672cf305b06fdb20', 'house_seed': 'f6f62244ac0f15c9a8f1d86ec75597fae91bfb81e45604ee8279080ba4f3fe90', 'expire_timestamp': 1544185101, 'signature': 'SIG_K1_KeErbDJ7XPLgmQuTJMMUcfeJKW3RRqXRrPods5uHdPszSKMGThmGw4XQunJmGXKTAnYxKuHQu5TBwtu2NMVwCR8WXPJE9W', 'status': 1, 'fail_count': 0, 'created_at': 1544184984.4921477, 'environment': 'PRO'}] (Background on this error at: http://sqlalche.me/e/gkpj)
2018-12-07 12:16:24,773 reveal_service.py[line:144] ERROR 〓REVEAL〓 房间新建后第一次开奖，且无人下注 开奖失败 roomid=21 (pymysql.err.IntegrityError) (1062, "Duplicate entry '21-2' for key 'uix_id_name'") [SQL: 'INSERT INTO room_seed (room_id, game_id, house_seed_hash, house_seed, expire_timestamp, signature, status, fail_count, created_at, environment) VALUES (%(room_id)s, %(game_id)s, %(house_seed_hash)s, %(house_seed)s, %(expire_timestamp)s, %(signature)s, %(status)s, %(fail_count)s, %(created_at)s, %(environment)s)'] [parameters: {'room_id': 21, 'game_id': 2, 'house_seed_hash': '2ba18a380bfcbf04ce4f98869fbef687007772d3f15a3ab93a2826f656edf0a0', 'house_seed': '43d67fd32cffaa9e07c8e451603c41e24fa540a60ec15868aedc68ffe7579cbe', 'expire_timestamp': 1544185101, 'signature': 'SIG_K1_Kg2YtHQJzZc21zERGr2TNnWoYiNonwo9E1PSPwA74tWgzCVSxshXWULGaq69NadxFt2ugJmpJYdLkgspSUqL66rLQVC9yS', 'status': 1, 'fail_count': 0, 'created_at': 1544184984.6075947, 'environment': 'PRO'}] (Background on this error at: http://sqlalche.me/e/gkpj)
2018-12-07 12:16:24,789 reveal_service.py[line:144] ERROR 〓REVEAL〓 房间新建后第一次开奖，且无人下注 开奖失败 roomid=21 (pymysql.err.IntegrityError) (1062, "Duplicate entry '21-2' for key 'uix_id_name'") [SQL: 'INSERT INTO room_seed (room_id, game_id, house_seed_hash, house_seed, expire_timestamp, signature, status, fail_count, created_at, environment) VALUES (%(room_id)s, %(game_id)s, %(house_seed_hash)s, %(house_seed)s, %(expire_timestamp)s, %(signature)s, %(status)s, %(fail_count)s, %(created_at)s, %(environment)s)'] [parameters: {'room_id': 21, 'game_id': 2, 'house_seed_hash': 'bd24526a1de44fe87c522571f7d8ba8a7efb2c4aec0e062a73cddd2379bfc3c5', 'house_seed': 'fde07710ef496b2635bd2c21bcc8c8487aad32c0e0c59dbf8ae42eaa886810b6', 'expire_timestamp': 1544185100, 'signature': 'SIG_K1_KhjeUMVDcGcpBcBTXxsHXiMJjRmSLFGGV9fC2RDRYp5tHxVzfwWHR1zc4Nq9KsZ3k13QhWF3UzVKeogTFa6Nrj5XoXodMD', 'status': 1, 'fail_count': 0, 'created_at': 1544184984.5798945, 'environment': 'PRO'}] (Background on this error at: http://sqlalche.me/e/gkpj)
2018-12-07 12:16:24,973 reveal_service.py[line:144] ERROR 〓REVEAL〓 房间新建后第一次开奖，且无人下注 开奖失败 roomid=21 (pymysql.err.IntegrityError) (1062, "Duplicate entry '21-2' for key 'uix_id_name'") [SQL: 'INSERT INTO room_seed (room_id, game_id, house_seed_hash, house_seed, expire_timestamp, signature, status, fail_count, created_at, environment) VALUES (%(room_id)s, %(game_id)s, %(house_seed_hash)s, %(house_seed)s, %(expire_timestamp)s, %(signature)s, %(status)s, %(fail_count)s, %(created_at)s, %(environment)s)'] [parameters: {'room_id': 21, 'game_id': 2, 'house_seed_hash': '76d4966bc8815357e2e7f0e47a58ceb7498a787089e5edbfa2e75d9e786a84a5', 'house_seed': 'e0b03da2f21bf2544a3ab1f116ffe401584c110c5c1be0886fc3f5e87dc4f7c4', 'expire_timestamp': 1544185100, 'signature': 'SIG_K1_KbjoWh1hMXpGeok9oYpukYvx4wuciZ5x11RwDWkMw8vErzGczM6KCKQ7NVEg9uQZhDcWiqPXb9SYRsgE1r8s2EQ8SJEy6R', 'status': 1, 'fail_count': 0, 'created_at': 1544184984.9669745, 'environment': 'PRO'}] (Background on this error at: http://sqlalche.me/e/gkpj)
2018-12-07 12:19:11,450 connector.py[line:28] ERROR invalid room status roomid=22 gameid=1 异常已被处理
2018-12-07 12:19:11,559 connector.py[line:28] ERROR invalid room status roomid=22 gameid=1 异常已被处理
2018-12-07 12:19:12,038 connector.py[line:28] ERROR invalid room status roomid=22 gameid=1 异常已被处理
2018-12-07 12:19:12,438 connector.py[line:28] ERROR invalid room status roomid=22 gameid=1 异常已被处理
2018-12-07 12:19:12,696 connector.py[line:28] ERROR invalid room status roomid=22 gameid=1 异常已被处理
2018-12-07 12:19:12,771 reveal_service.py[line:144] ERROR 〓REVEAL〓 房间新建后第一次开奖，且无人下注 开奖失败 roomid=22 (pymysql.err.IntegrityError) (1062, "Duplicate entry '22-2' for key 'uix_id_name'") [SQL: 'INSERT INTO room_seed (room_id, game_id, house_seed_hash, house_seed, expire_timestamp, signature, status, fail_count, created_at, environment) VALUES (%(room_id)s, %(game_id)s, %(house_seed_hash)s, %(house_seed)s, %(expire_timestamp)s, %(signature)s, %(status)s, %(fail_count)s, %(created_at)s, %(environment)s)'] [parameters: {'room_id': 22, 'game_id': 2, 'house_seed_hash': '5b8ad69331ebbe6795c9e8cc38d1473ae25451f83898cdd32e565ad29f6ed975', 'house_seed': 'a12f3adf854f45bc7a6d62b8003a38d566c76c18a8b1c765eace9b84ee1b2e20', 'expire_timestamp': 1544185271, 'signature': 'SIG_K1_Jw6pFuoebxYmmuoHg7FnrfgsYpmrBtKRgFgRMvNY8H6kasZLmW2kAMfHacjLDnnBgssUYEhvVeCJqSHtQsSdcjhCJJa3LM', 'status': 1, 'fail_count': 0, 'created_at': 1544185152.7296023, 'environment': 'PRO'}] (Background on this error at: http://sqlalche.me/e/gkpj)
2018-12-07 12:19:13,759 reveal_service.py[line:144] ERROR 〓REVEAL〓 房间新建后第一次开奖，且无人下注 开奖失败 roomid=22 (pymysql.err.IntegrityError) (1062, "Duplicate entry '22-2' for key 'uix_id_name'") [SQL: 'INSERT INTO room_seed (room_id, game_id, house_seed_hash, house_seed, expire_timestamp, signature, status, fail_count, created_at, environment) VALUES (%(room_id)s, %(game_id)s, %(house_seed_hash)s, %(house_seed)s, %(expire_timestamp)s, %(signature)s, %(status)s, %(fail_count)s, %(created_at)s, %(environment)s)'] [parameters: {'room_id': 22, 'game_id': 2, 'house_seed_hash': 'ceec923d13f6fb8727e29aabad851d9ca591720f15e72f0949b15f0d51f99052', 'house_seed': '5995b15e22f72516a71bdefc0b7247b345e92dbe92cdcfacb984b71018521671', 'expire_timestamp': 1544185272, 'signature': 'SIG_K1_K8TdLMMPXiVqgzdbwJTmsZkjKaJE7TnR3Xb7EZ2kxpfHsACs3kTHAQLpPzb5bCRJqAUwETbrpbq9ZbpRgr3SV8V86Peh1x', 'status': 1, 'fail_count': 0, 'created_at': 1544185153.6282892, 'environment': 'PRO'}] (Background on this error at: http://sqlalche.me/e/gkpj)
2018-12-07 12:19:13,765 reveal_service.py[line:144] ERROR 〓REVEAL〓 房间新建后第一次开奖，且无人下注 开奖失败 roomid=22 (pymysql.err.IntegrityError) (1062, "Duplicate entry '22-2' for key 'uix_id_name'") [SQL: 'INSERT INTO room_seed (room_id, game_id, house_seed_hash, house_seed, expire_timestamp, signature, status, fail_count, created_at, environment) VALUES (%(room_id)s, %(game_id)s, %(house_seed_hash)s, %(house_seed)s, %(expire_timestamp)s, %(signature)s, %(status)s, %(fail_count)s, %(created_at)s, %(environment)s)'] [parameters: {'room_id': 22, 'game_id': 2, 'house_seed_hash': '208a124d9b4830de9b52809080c678489bfe008d25889e6012d82f05f71cbd03', 'house_seed': 'dbc393329da1f089d52631e42e5ea6e7de62dd02415fd752aa0af8ffeb70d3d7', 'expire_timestamp': 1544185272, 'signature': 'SIG_K1_Kj2HHavkcMLQp7CuKpcvhTaq4UqFTQJDNj4pGhexuy7THpscrVNnqdRQfkrwPHv2rNyaLxUqmepgg5zE9p6S6WKqmfsESN', 'status': 1, 'fail_count': 0, 'created_at': 1544185153.6297376, 'environment': 'PRO'}] (Background on this error at: http://sqlalche.me/e/gkpj)
2018-12-07 12:19:13,829 reveal_service.py[line:144] ERROR 〓REVEAL〓 房间新建后第一次开奖，且无人下注 开奖失败 roomid=22 (pymysql.err.IntegrityError) (1062, "Duplicate entry '22-2' for key 'uix_id_name'") [SQL: 'INSERT INTO room_seed (room_id, game_id, house_seed_hash, house_seed, expire_timestamp, signature, status, fail_count, created_at, environment) VALUES (%(room_id)s, %(game_id)s, %(house_seed_hash)s, %(house_seed)s, %(expire_timestamp)s, %(signature)s, %(status)s, %(fail_count)s, %(created_at)s, %(environment)s)'] [parameters: {'room_id': 22, 'game_id': 2, 'house_seed_hash': '6fe3361885fecf2a31be009644a02c4fba72a7087a038df00ed944e5af86345e', 'house_seed': 'e5ff033c85c2007c0b5db1380c5e5e71e4bd528500121a658dd03ed2534b7b1a', 'expire_timestamp': 1544185271, 'signature': 'SIG_K1_KiTjabJD4CquyDrKmFadwdnJTA6iPFsKauep2phoYRn3gXhEVwgHqsuincyEDkXm18w3QTvnrwen83D64KkBiy7Ugi1Eja', 'status': 1, 'fail_count': 0, 'created_at': 1544185153.7511883, 'environment': 'PRO'}] (Background on this error at: http://sqlalche.me/e/gkpj)
2018-12-07 12:19:13,834 reveal_service.py[line:144] ERROR 〓REVEAL〓 房间新建后第一次开奖，且无人下注 开奖失败 roomid=22 (pymysql.err.IntegrityError) (1062, "Duplicate entry '22-2' for key 'uix_id_name'") [SQL: 'INSERT INTO room_seed (room_id, game_id, house_seed_hash, house_seed, expire_timestamp, signature, status, fail_count, created_at, environment) VALUES (%(room_id)s, %(game_id)s, %(house_seed_hash)s, %(house_seed)s, %(expire_timestamp)s, %(signature)s, %(status)s, %(fail_count)s, %(created_at)s, %(environment)s)'] [parameters: {'room_id': 22, 'game_id': 2, 'house_seed_hash': '546cb5b32c1cfe5aa08695f5f023be986d0d187d01c6ee5fca2ba3672923fea0', 'house_seed': '9a012cbcc9102fb14c3d7e201b65a1852e074226f982c0c6109490f7366fa87e', 'expire_timestamp': 1544185272, 'signature': 'SIG_K1_JuSRiZy1CESwLx2xRGd6gh7R6DZPypbgVU6dk9t5hzjeUFEdC93dKAoghQqKuGrq5hSkHMgm9mGNY2ZSLzBA5zrtUeofvM', 'status': 1, 'fail_count': 0, 'created_at': 1544185153.8283844, 'environment': 'PRO'}] (Background on this error at: http://sqlalche.me/e/gkpj)
2018-12-07 15:48:47,634 reveal_service.py[line:144] ERROR 〓REVEAL〓 房间新建后第一次开奖，且无人下注 开奖失败 roomid=23 b'\x1b[31mError 3050003: eosio_assert_message assertion failure\x1b[0m\n\x1b[33mError Details:\nassertion failure with message: 100016 room not found\npending console output: \x1b[0m\n'
2018-12-07 15:48:48,718 reveal_service.py[line:144] ERROR 〓REVEAL〓 房间新建后第一次开奖，且无人下注 开奖失败 roomid=23 b'\x1b[31mError 3050003: eosio_assert_message assertion failure\x1b[0m\n\x1b[33mError Details:\nassertion failure with message: 100016 room not found\npending console output: \x1b[0m\n'
2018-12-07 16:00:22,564 seed_service.py[line:125] ERROR no seed data
2018-12-07 16:00:22,564 seed_service.py[line:44] ERROR get_seed 异常 =no seed data
2018-12-07 16:00:22,564 views.py[line:78] ERROR api get_seed 异常=no seed data
2018-12-07 16:00:27,285 reveal_service.py[line:128] ERROR [async_call_sub] 异常，重试1次 id=27941 roomid=22 game_id=28 =b'\x1b[31mError 3050003: eosio_assert_message assertion failure\x1b[0m\n\x1b[33mError Details:\nassertion failure with message: 100013 invalid room status\npending console output: \x1b[0m\n'
2018-12-07 16:01:51,710 reveal_service.py[line:128] ERROR [async_call_sub] 异常，重试1次 id=27946 roomid=22 game_id=29 =b'error 2018-12-07T16:01:51.709 thread-0  main.cpp:3151                 main                 ] Failed with error: Parse Error (4)\nUnexpected char \'60\' in ""\n\n\n'
2018-12-07 16:01:53,680 reveal_service.py[line:128] ERROR [async_call_sub] 异常，重试1次 id=27949 roomid=6 game_id=2632 =b'\x1b[31mError 3040005: Expired Transaction\x1b[0m\n\x1b[32mPlease increase the expiration time of your transaction!\x1b[0m\n\x1b[33mError Details:\nexpired transaction ba5bfdca5d8aca4b053df19cad14488484b7451273611aa528ea215aacba31dd\x1b[0m\n'
2018-12-07 16:02:36,563 reveal_service.py[line:128] ERROR [async_call_sub] 异常，重试1次 id=27950 roomid=8 game_id=2105 =b'\x1b[31mError 3040005: Expired Transaction\x1b[0m\n\x1b[32mPlease increase the expiration time of your transaction!\x1b[0m\n\x1b[33mError Details:\nexpired transaction 840b83b2fe0aac299f0fcbca888138b621c6b6a7527e63cf715e7918906d8afc\x1b[0m\n'
2018-12-07 16:03:08,361 reveal_service.py[line:128] ERROR [async_call_sub] 异常，重试1次 id=27951 roomid=12 game_id=658 =b'error 2018-12-07T16:03:08.360 thread-0  main.cpp:3151                 main                 ] Failed with error: Parse Error (4)\nUnexpected char \'60\' in ""\n\n\n'
2018-12-07 16:03:38,870 reveal_service.py[line:128] ERROR [async_call_sub] 异常，重试1次 id=27955 roomid=22 game_id=31 =b"\x1b[31mError 3040007: Invalid Reference Block\x1b[0m\n\x1b[32mEnsure that the reference block exist in the blockchain!\x1b[0m\n\x1b[33mError Details:\nTransaction's reference block did not match. Is this transaction from a different fork?\x1b[0m\n"
2018-12-07 16:03:40,851 reveal_service.py[line:128] ERROR [async_call_sub] 异常，重试2次 id=27955 roomid=22 game_id=31 =b'\x1b[31mError 3040005: Expired Transaction\x1b[0m\n\x1b[32mPlease increase the expiration time of your transaction!\x1b[0m\n\x1b[33mError Details:\nexpired transaction dad1237fa71372fd92d72de3ac2eee00b3947c8b59e1a0ea2117521230900797\x1b[0m\n'
2018-12-07 16:04:33,638 reveal_service.py[line:128] ERROR [async_call_sub] 异常，重试1次 id=27959 roomid=6 game_id=2635 =b'\x1b[31mError 3040005: Expired Transaction\x1b[0m\n\x1b[32mPlease increase the expiration time of your transaction!\x1b[0m\n\x1b[33mError Details:\nexpired transaction 593836d095f1dd9e4dc4b577ca3041430bbd244145b5fcffa229c4a575a97104\x1b[0m\n'
2018-12-07 16:05:27,530 reveal_service.py[line:128] ERROR [async_call_sub] 异常，重试1次 id=27963 roomid=22 game_id=33 =b'\x1b[31mError 3040005: Expired Transaction\x1b[0m\n\x1b[32mPlease increase the expiration time of your transaction!\x1b[0m\n\x1b[33mError Details:\nexpired transaction 439919c1d91734a8c54802624249a3355b7872a5cc805753d1fe0921bed80493\x1b[0m\n'
2018-12-07 16:05:28,147 reveal_service.py[line:128] ERROR [async_call_sub] 异常，重试1次 id=27964 roomid=6 game_id=2636 =b"\x1b[31mError 3040007: Invalid Reference Block\x1b[0m\n\x1b[32mEnsure that the reference block exist in the blockchain!\x1b[0m\n\x1b[33mError Details:\nTransaction's reference block did not match. Is this transaction from a different fork?\x1b[0m\n"
2018-12-07 16:05:30,539 reveal_service.py[line:128] ERROR [async_call_sub] 异常，重试2次 id=27964 roomid=6 game_id=2636 =b"\x1b[31mError 3040007: Invalid Reference Block\x1b[0m\n\x1b[32mEnsure that the reference block exist in the blockchain!\x1b[0m\n\x1b[33mError Details:\nTransaction's reference block did not match. Is this transaction from a different fork?\x1b[0m\n"
2018-12-07 16:05:32,190 reveal_service.py[line:128] ERROR [async_call_sub] 异常，重试3次 id=27964 roomid=6 game_id=2636 =b"\x1b[31mError 3040007: Invalid Reference Block\x1b[0m\n\x1b[32mEnsure that the reference block exist in the blockchain!\x1b[0m\n\x1b[33mError Details:\nTransaction's reference block did not match. Is this transaction from a different fork?\x1b[0m\n"
2018-12-07 16:05:59,689 reveal_service.py[line:128] ERROR [async_call_sub] 异常，重试2次 id=27963 roomid=22 game_id=33 =b'error 2018-12-07T16:05:59.688 thread-0  main.cpp:3151                 main                 ] Failed with error: Parse Error (4)\nUnexpected char \'60\' in ""\n\n\n'
2018-12-07 16:06:01,357 reveal_service.py[line:128] ERROR [async_call_sub] 异常，重试3次 id=27963 roomid=22 game_id=33 =b"\x1b[31mError 3040007: Invalid Reference Block\x1b[0m\n\x1b[32mEnsure that the reference block exist in the blockchain!\x1b[0m\n\x1b[33mError Details:\nTransaction's reference block did not match. Is this transaction from a different fork?\x1b[0m\n"
2018-12-07 16:06:59,856 reveal_service.py[line:128] ERROR [async_call_sub] 异常，重试1次 id=27968 roomid=8 game_id=2110 =b"\x1b[31mError 3040007: Invalid Reference Block\x1b[0m\n\x1b[32mEnsure that the reference block exist in the blockchain!\x1b[0m\n\x1b[33mError Details:\nTransaction's reference block did not match. Is this transaction from a different fork?\x1b[0m\n"
2018-12-07 16:07:10,108 reveal_service.py[line:128] ERROR [async_call_sub] 异常，重试1次 id=27967 roomid=12 game_id=662 =b'error 2018-12-07T16:07:10.106 thread-0  main.cpp:3151                 main                 ] Failed with error: Parse Error (4)\nUnexpected char \'60\' in ""\n\n\n'
2018-12-07 16:07:12,056 reveal_service.py[line:128] ERROR [async_call_sub] 异常，重试2次 id=27967 roomid=12 game_id=662 =b"\x1b[31mError 3040007: Invalid Reference Block\x1b[0m\n\x1b[32mEnsure that the reference block exist in the blockchain!\x1b[0m\n\x1b[33mError Details:\nTransaction's reference block did not match. Is this transaction from a different fork?\x1b[0m\n"
2018-12-07 16:10:16,630 reveal_service.py[line:128] ERROR [async_call_sub] 异常，重试1次 id=27973 roomid=8 game_id=2113 =b'error 2018-12-07T16:10:16.629 thread-0  main.cpp:3151                 main                 ] Failed with error: Parse Error (4)\nUnexpected char \'60\' in ""\n\n\n'
2018-12-07 16:39:49,278 connector.py[line:28] ERROR invalid room status roomid=24 gameid=1 异常已被处理
2018-12-07 16:39:49,547 connector.py[line:28] ERROR invalid room status roomid=24 gameid=1 异常已被处理
2018-12-07 16:39:49,774 connector.py[line:28] ERROR invalid room status roomid=24 gameid=1 异常已被处理
2018-12-07 16:39:49,851 connector.py[line:28] ERROR invalid room status roomid=24 gameid=1 异常已被处理
2018-12-07 16:39:50,541 reveal_service.py[line:144] ERROR 〓REVEAL〓 房间新建后第一次开奖，且无人下注 开奖失败 roomid=24 (pymysql.err.IntegrityError) (1062, "Duplicate entry '24-2' for key 'uix_id_name'") [SQL: 'INSERT INTO room_seed (room_id, game_id, house_seed_hash, house_seed, expire_timestamp, signature, status, fail_count, created_at, environment) VALUES (%(room_id)s, %(game_id)s, %(house_seed_hash)s, %(house_seed)s, %(expire_timestamp)s, %(signature)s, %(status)s, %(fail_count)s, %(created_at)s, %(environment)s)'] [parameters: {'room_id': 24, 'game_id': 2, 'house_seed_hash': 'bdf48c5538917e83356dc72dbeaf57f2380da7b725587f47e826087c49b9503a', 'house_seed': 'fe155a75004f8d5029192947561d8aed02c42dba47c9009829c84635fbf8e562', 'expire_timestamp': 1544200908, 'signature': 'SIG_K1_KhXwA3K69Rbz9m4MT558Dr3h5zf8zCUb1YQcQoL3SWeArcgcDfVDPTBqrdumiuc8S79Ey31zCDPkjBBian9mjqSA9pyzyK', 'status': 1, 'fail_count': 0, 'created_at': 1544200790.464529, 'environment': 'PRO'}] (Background on this error at: http://sqlalche.me/e/gkpj)
2018-12-07 16:39:50,601 reveal_service.py[line:144] ERROR 〓REVEAL〓 房间新建后第一次开奖，且无人下注 开奖失败 roomid=24 (pymysql.err.IntegrityError) (1062, "Duplicate entry '24-2' for key 'uix_id_name'") [SQL: 'INSERT INTO room_seed (room_id, game_id, house_seed_hash, house_seed, expire_timestamp, signature, status, fail_count, created_at, environment) VALUES (%(room_id)s, %(game_id)s, %(house_seed_hash)s, %(house_seed)s, %(expire_timestamp)s, %(signature)s, %(status)s, %(fail_count)s, %(created_at)s, %(environment)s)'] [parameters: {'room_id': 24, 'game_id': 2, 'house_seed_hash': 'a7782c0f6042c85de2db5518c9643d6376c7946324235cb28c6cb571c9d95062', 'house_seed': '37da52f2beadc42f5b8d4695ad356492cd2fdf747da1d11abfd2a266b5fc0790', 'expire_timestamp': 1544200908, 'signature': 'SIG_K1_K1YhituvmyVWsHwAdzEJaNkgaL7uiVG7KKNzS3fszFSkBKSN95qbBRKfjVtEA7bE22uDdG5XAktv5eAbETgN2V9RDqY5pz', 'status': 1, 'fail_count': 0, 'created_at': 1544200790.5405006, 'environment': 'PRO'}] (Background on this error at: http://sqlalche.me/e/gkpj)
2018-12-07 16:39:50,897 reveal_service.py[line:144] ERROR 〓REVEAL〓 房间新建后第一次开奖，且无人下注 开奖失败 roomid=24 (pymysql.err.IntegrityError) (1062, "Duplicate entry '24-2' for key 'uix_id_name'") [SQL: 'INSERT INTO room_seed (room_id, game_id, house_seed_hash, house_seed, expire_timestamp, signature, status, fail_count, created_at, environment) VALUES (%(room_id)s, %(game_id)s, %(house_seed_hash)s, %(house_seed)s, %(expire_timestamp)s, %(signature)s, %(status)s, %(fail_count)s, %(created_at)s, %(environment)s)'] [parameters: {'room_id': 24, 'game_id': 2, 'house_seed_hash': 'c68a125a75d1c760b9520626a79d1f61989f21748b6402b24b596ce93f461958', 'house_seed': 'e5ac231923a33aa41b2eb7d5dd2d94fe0fcb29be9c3e6bf6089576e0b294aa7a', 'expire_timestamp': 1544200908, 'signature': 'SIG_K1_K6BW3VrRndyWTpjm1xV7E6AXiipkkJy8mCrGeTxJxF9hf1FLfdyhQFmDcL49zcXDvDqfkg3JEPf2KVZ1exQRkFmX5c3j22', 'status': 1, 'fail_count': 0, 'created_at': 1544200790.8371873, 'environment': 'PRO'}] (Background on this error at: http://sqlalche.me/e/gkpj)
2018-12-07 16:39:50,904 reveal_service.py[line:144] ERROR 〓REVEAL〓 房间新建后第一次开奖，且无人下注 开奖失败 roomid=24 (pymysql.err.IntegrityError) (1062, "Duplicate entry '24-2' for key 'uix_id_name'") [SQL: 'INSERT INTO room_seed (room_id, game_id, house_seed_hash, house_seed, expire_timestamp, signature, status, fail_count, created_at, environment) VALUES (%(room_id)s, %(game_id)s, %(house_seed_hash)s, %(house_seed)s, %(expire_timestamp)s, %(signature)s, %(status)s, %(fail_count)s, %(created_at)s, %(environment)s)'] [parameters: {'room_id': 24, 'game_id': 2, 'house_seed_hash': '223070f216c8bfd24a92d400e81bce3f3a5474fac9eac4ab028163ff16e9c58c', 'house_seed': '62a1c70e5e54d58781a2cb7bce9113b4f825e06bbbc2f5e0576b93436908f00c', 'expire_timestamp': 1544200908, 'signature': 'SIG_K1_K7u4gyEhqcjnoACtprLCMXp4xJMMX7Etfbpf5dd73wdiTEa1equCTJY7fA6oMopmTMyRCbMjJ4EkUKtV3C5zguKKtxmuFb', 'status': 1, 'fail_count': 0, 'created_at': 1544200790.8977485, 'environment': 'PRO'}] (Background on this error at: http://sqlalche.me/e/gkpj)
2018-12-07 19:55:13,103 reveal_service.py[line:128] ERROR [async_call_sub] 异常，重试1次 id=30341 roomid=25 game_id=136 =b'\x1b[31mError 3050003: eosio_assert_message assertion failure\x1b[0m\n\x1b[33mError Details:\nassertion failure with message: 100013 invalid room status\npending console output: \x1b[0m\n'
2018-12-07 20:08:00,926 reveal_service.py[line:128] ERROR [async_call_sub] 异常，重试1次 id=30490 roomid=22 game_id=296 =b'\x1b[31mError 3050003: eosio_assert_message assertion failure\x1b[0m\n\x1b[33mError Details:\nassertion failure with message: 100013 invalid room status\npending console output: \x1b[0m\n'
2018-12-08 02:28:19,877 seed_service.py[line:125] ERROR no seed data
2018-12-08 02:28:19,877 seed_service.py[line:44] ERROR get_seed 异常 =no seed data
2018-12-08 02:28:19,877 views.py[line:78] ERROR api get_seed 异常=no seed data
2018-12-08 02:30:30,174 seed_service.py[line:125] ERROR no seed data
2018-12-08 02:30:30,174 seed_service.py[line:44] ERROR get_seed 异常 =no seed data
2018-12-08 02:30:30,174 views.py[line:78] ERROR api get_seed 异常=no seed data
2018-12-08 02:33:22,355 seed_service.py[line:125] ERROR no seed data
2018-12-08 02:33:22,355 seed_service.py[line:44] ERROR get_seed 异常 =no seed data
2018-12-08 02:33:22,355 views.py[line:78] ERROR api get_seed 异常=no seed data
2018-12-08 02:42:36,612 reveal_service.py[line:128] ERROR [async_call_sub] 异常，重试1次 id=34720 roomid=11 game_id=1847 =b'\x1b[31mError 3050003: eosio_assert_message assertion failure\x1b[0m\n\x1b[33mError Details:\nassertion failure with message: 100013 invalid room status\npending console output: \x1b[0m\n'
2018-12-08 03:51:55,465 reveal_service.py[line:128] ERROR [async_call_sub] 异常，重试1次 id=35509 roomid=16 game_id=1217 =b'\x1b[31mError 3050003: eosio_assert_message assertion failure\x1b[0m\n\x1b[33mError Details:\nassertion failure with message: 100013 invalid room status\npending console output: \x1b[0m\n'
2018-12-08 05:53:42,765 reveal_service.py[line:128] ERROR [async_call_sub] 异常，重试1次 id=36872 roomid=22 game_id=675 =b'\x1b[31mError 3050003: eosio_assert_message assertion failure\x1b[0m\n\x1b[33mError Details:\nassertion failure with message: 100013 invalid room status\npending console output: \x1b[0m\n'
2018-12-08 06:36:24,629 reveal_service.py[line:128] ERROR [async_call_sub] 异常，重试1次 id=37309 roomid=6 game_id=3617 =b'\x1b[31mError 3050003: eosio_assert_message assertion failure\x1b[0m\n\x1b[33mError Details:\nassertion failure with message: 100013 invalid room status\npending console output: \x1b[0m\n'
2018-12-08 06:54:23,631 seed_service.py[line:125] ERROR no seed data
2018-12-08 06:54:23,631 seed_service.py[line:44] ERROR get_seed 异常 =no seed data
2018-12-08 06:54:23,631 views.py[line:78] ERROR api get_seed 异常=no seed data
2018-12-08 07:29:37,089 reveal_service.py[line:128] ERROR [async_call_sub] 异常，重试1次 id=37854 roomid=24 game_id=1018 =b'\x1b[31mError 3050003: eosio_assert_message assertion failure\x1b[0m\n\x1b[33mError Details:\nassertion failure with message: 100013 invalid room status\npending console output: \x1b[0m\n'
2018-12-08 09:25:48,587 reveal_service.py[line:128] ERROR [async_call_sub] 异常，重试1次 id=39041 roomid=25 game_id=1061 =b'\x1b[31mError 3050003: eosio_assert_message assertion failure\x1b[0m\n\x1b[33mError Details:\nassertion failure with message: 100013 invalid room status\npending console output: \x1b[0m\n'
2018-12-08 09:26:30,622 reveal_service.py[line:128] ERROR [async_call_sub] 异常，重试1次 id=39047 roomid=6 game_id=3810 =b'\x1b[31mError 3050003: eosio_assert_message assertion failure\x1b[0m\n\x1b[33mError Details:\nassertion failure with message: 100013 invalid room status\npending console output: \x1b[0m\n'
2018-12-08 09:38:57,254 seed_service.py[line:125] ERROR no seed data
2018-12-08 09:38:57,254 seed_service.py[line:44] ERROR get_seed 异常 =no seed data
2018-12-08 09:38:57,254 views.py[line:78] ERROR api get_seed 异常=no seed data
2018-12-08 09:46:18,228 connector.py[line:28] ERROR invalid room status roomid=26 gameid=1 异常已被处理
2018-12-08 09:46:18,323 connector.py[line:28] ERROR invalid room status roomid=26 gameid=1 异常已被处理
2018-12-08 09:46:18,506 connector.py[line:28] ERROR invalid room status roomid=26 gameid=1 异常已被处理
2018-12-08 09:46:19,056 connector.py[line:28] ERROR invalid room status roomid=26 gameid=1 异常已被处理
2018-12-08 09:46:20,166 reveal_service.py[line:144] ERROR 〓REVEAL〓 房间新建后第一次开奖，且无人下注 开奖失败 roomid=26 (pymysql.err.IntegrityError) (1062, "Duplicate entry '26-2' for key 'uix_id_name'") [SQL: 'INSERT INTO room_seed (room_id, game_id, house_seed_hash, house_seed, expire_timestamp, signature, status, fail_count, created_at, environment) VALUES (%(room_id)s, %(game_id)s, %(house_seed_hash)s, %(house_seed)s, %(expire_timestamp)s, %(signature)s, %(status)s, %(fail_count)s, %(created_at)s, %(environment)s)'] [parameters: {'room_id': 26, 'game_id': 2, 'house_seed_hash': 'acd31e96291a8c0cea39984f8edd021625fc721731305e6ef6721f3df2a2731c', 'house_seed': '69b17c4b0e7aeaeaec3f50975808ba086b4666228bafb8a002b0e822143178e2', 'expire_timestamp': 1544262497, 'signature': 'SIG_K1_K9m8LXKSjaoNzi93k2YGtioCUuBQZy8JGv6m1JpF85yN5hGF5M2PA8bYvHig13J4SmxNdUa3AypEk8jeiC3gmMWzvgJ73v', 'status': 1, 'fail_count': 0, 'created_at': 1544262380.1294413, 'environment': 'PRO'}] (Background on this error at: http://sqlalche.me/e/gkpj)
2018-12-08 09:46:20,255 reveal_service.py[line:144] ERROR 〓REVEAL〓 房间新建后第一次开奖，且无人下注 开奖失败 roomid=26 (pymysql.err.IntegrityError) (1062, "Duplicate entry '26-2' for key 'uix_id_name'") [SQL: 'INSERT INTO room_seed (room_id, game_id, house_seed_hash, house_seed, expire_timestamp, signature, status, fail_count, created_at, environment) VALUES (%(room_id)s, %(game_id)s, %(house_seed_hash)s, %(house_seed)s, %(expire_timestamp)s, %(signature)s, %(status)s, %(fail_count)s, %(created_at)s, %(environment)s)'] [parameters: {'room_id': 26, 'game_id': 2, 'house_seed_hash': '2807c8154757bc01f8f010521dd2fc84388e3b86dcbb313cb243a91510321be9', 'house_seed': 'dfb19ae8e3cf7901582464d335562d24dc795f44990afae7b7ec7a4c954618d3', 'expire_timestamp': 1544262497, 'signature': 'SIG_K1_KY9dJ9UN58xuGMWuXESZkFN4Cv4KqTX19do1i3z8KXEQ2pqgB5yDudfDALUsLthxUav2E4EJjUMByRqafdBekC8pquECfK', 'status': 1, 'fail_count': 0, 'created_at': 1544262380.1732836, 'environment': 'PRO'}] (Background on this error at: http://sqlalche.me/e/gkpj)
2018-12-08 09:46:20,281 reveal_service.py[line:144] ERROR 〓REVEAL〓 房间新建后第一次开奖，且无人下注 开奖失败 roomid=26 (pymysql.err.IntegrityError) (1062, "Duplicate entry '26-2' for key 'uix_id_name'") [SQL: 'INSERT INTO room_seed (room_id, game_id, house_seed_hash, house_seed, expire_timestamp, signature, status, fail_count, created_at, environment) VALUES (%(room_id)s, %(game_id)s, %(house_seed_hash)s, %(house_seed)s, %(expire_timestamp)s, %(signature)s, %(status)s, %(fail_count)s, %(created_at)s, %(environment)s)'] [parameters: {'room_id': 26, 'game_id': 2, 'house_seed_hash': '0fe577653c3560ea76c872581adc246b96170efb5faebe35c791b55571bdc070', 'house_seed': '0012daeacd4f0807dd2e10219b337b4478d0274373b84821a62b13f39d05890d', 'expire_timestamp': 1544262497, 'signature': 'SIG_K1_KYwaywK2ZXt6jSUV76VEbUcmE5FT5kpr49ebUEtfqtF3prKWigo8uvdBgddsaigfJZaeP47ve2FaD6Bc1CK3LpCPrMjgKV', 'status': 1, 'fail_count': 0, 'created_at': 1544262380.2475617, 'environment': 'PRO'}] (Background on this error at: http://sqlalche.me/e/gkpj)
2018-12-08 09:46:20,284 reveal_service.py[line:144] ERROR 〓REVEAL〓 房间新建后第一次开奖，且无人下注 开奖失败 roomid=26 (pymysql.err.IntegrityError) (1062, "Duplicate entry '26-2' for key 'uix_id_name'") [SQL: 'INSERT INTO room_seed (room_id, game_id, house_seed_hash, house_seed, expire_timestamp, signature, status, fail_count, created_at, environment) VALUES (%(room_id)s, %(game_id)s, %(house_seed_hash)s, %(house_seed)s, %(expire_timestamp)s, %(signature)s, %(status)s, %(fail_count)s, %(created_at)s, %(environment)s)'] [parameters: {'room_id': 26, 'game_id': 2, 'house_seed_hash': '205c890b5c5c9bb1e1aecb0f9dcdfe0f587197acc42787ef49eb60c5d506e969', 'house_seed': 'fd6d9baceecdd9149b00fb15b563213007bb309f2c475093a182b82521c4d52e', 'expire_timestamp': 1544262498, 'signature': 'SIG_K1_K2pdebfp9xxaSUVJiSp4YQ2taGLBWpMXnjK7ymHP1iQnqJzNChr8JAejmpPG759JWtU9xdGoCNfsEfywp6ePmSNnzctUgM', 'status': 1, 'fail_count': 0, 'created_at': 1544262380.2801404, 'environment': 'PRO'}] (Background on this error at: http://sqlalche.me/e/gkpj)
2018-12-08 10:10:40,793 reveal_service.py[line:128] ERROR [async_call_sub] 异常，重试1次 id=39529 roomid=6 game_id=3860 =b'\x1b[31mError 3050003: eosio_assert_message assertion failure\x1b[0m\n\x1b[33mError Details:\nassertion failure with message: 100013 invalid room status\npending console output: \x1b[0m\n'
2018-12-08 10:33:01,078 reveal_service.py[line:128] ERROR [async_call_sub] 异常，重试1次 id=39784 roomid=24 game_id=1226 =b'\x1b[31mError 3050003: eosio_assert_message assertion failure\x1b[0m\n\x1b[33mError Details:\nassertion failure with message: 100013 invalid room status\npending console output: \x1b[0m\n'
2018-12-08 11:33:54,483 reveal_service.py[line:128] ERROR [async_call_sub] 异常，重试1次 id=40476 roomid=1 game_id=4004 =b'\x1b[31mError 3050003: eosio_assert_message assertion failure\x1b[0m\n\x1b[33mError Details:\nassertion failure with message: 100013 invalid room status\npending console output: \x1b[0m\n'
2018-12-08 11:48:36,833 reveal_service.py[line:128] ERROR [async_call_sub] 异常，重试1次 id=40645 roomid=26 game_id=140 =b'\x1b[31mError 3050003: eosio_assert_message assertion failure\x1b[0m\n\x1b[33mError Details:\nassertion failure with message: 100013 invalid room status\npending console output: \x1b[0m\n'
